<?xml version='1.0'?>
<robot name="avp_landau_parallel"><link name="root_x"><inertial><origin xyz="0.000000 0.000000 0.000000" rpy="0.000000 0.000000 0.000000" /><mass value="0.040000" /><inertia ixx="0.000010" ixy="0.0" ixz="0.0" iyy="0.000011" iyz="0.0" izz="0.000011" /></inertial><visual><origin xyz="0.000000 0.000000 0.000000" rpy="0.000000 0.000000 0.000000" /><geometry><sphere radius="0.007662" /></geometry></visual><visual><origin xyz="-0.000000 0.030250 -0.017259" rpy="-0.000000 0.518478 1.570798" /><geometry><box size="0.069654 0.013931 0.013931" /></geometry></visual><visual><origin xyz="0.029703 0.000000 -0.000000" rpy="0.000000 0.000003 0.000000" /><geometry><box size="0.059407 0.013931 0.013931" /></geometry></visual><visual><origin xyz="-0.029703 0.000000 0.000000" rpy="0.000000 -0.000003 3.141593" /><geometry><box size="0.059407 0.013931 0.013931" /></geometry></visual><collision><origin xyz="0.000000 0.000000 0.000000" rpy="0.000000 0.000000 0.000000" /><geometry><sphere radius="0.007662" /></geometry></collision><collision><origin xyz="-0.000000 0.030250 -0.017259" rpy="-0.000000 0.518478 1.570798" /><geometry><box size="0.069654 0.013931 0.013931" /></geometry></collision><collision><origin xyz="0.029703 0.000000 -0.000000" rpy="0.000000 0.000003 0.000000" /><geometry><box size="0.059407 0.013931 0.013931" /></geometry></collision><collision><origin xyz="-0.029703 0.000000 0.000000" rpy="0.000000 -0.000003 3.141593" /><geometry><box size="0.059407 0.013931 0.013931" /></geometry></collision></link><link name="spine_01_x"><inertial><origin xyz="0.000000 0.000000 0.000000" rpy="0.000000 0.000000 0.000000" /><mass value="0.020000" /><inertia ixx="0.000010" ixy="0.0" ixz="0.0" iyy="0.000010" iyz="0.0" izz="0.000010" /></inertial><visual><origin xyz="0.000000 0.000000 0.000000" rpy="0.000000 0.000000 0.000000" /><geometry><sphere radius="0.009900" /></geometry></visual><visual><origin xyz="-0.000000 0.033983 -0.000000" rpy="0.000000 0.000000 1.570796" /><geometry><box size="0.067965 0.018000 0.018000" /></geometry></visual><collision><origin xyz="0.000000 0.000000 0.000000" rpy="0.000000 0.000000 0.000000" /><geometry><sphere radius="0.009900" /></geometry></collision><collision><origin xyz="-0.000000 0.033983 -0.000000" rpy="0.000000 0.000000 1.570796" /><geometry><box size="0.067965 0.018000 0.018000" /></geometry></collision></link><link name="spine_02_x"><inertial><origin xyz="0.000000 0.000000 0.000000" rpy="0.000000 0.000000 0.000000" /><mass value="0.020000" /><inertia ixx="0.000010" ixy="0.0" ixz="0.0" iyy="0.000010" iyz="0.0" izz="0.000010" /></inertial><visual><origin xyz="0.000000 0.000000 0.000000" rpy="0.000000 0.000000 0.000000" /><geometry><sphere radius="0.009900" /></geometry></visual><visual><origin xyz="0.000000 0.034653 -0.000000" rpy="0.000000 0.000000 1.570796" /><geometry><box size="0.069307 0.018000 0.018000" /></geometry></visual><collision><origin xyz="0.000000 0.000000 0.000000" rpy="0.000000 0.000000 0.000000" /><geometry><sphere radius="0.009900" /></geometry></collision><collision><origin xyz="0.000000 0.034653 -0.000000" rpy="0.000000 0.000000 1.570796" /><geometry><box size="0.069307 0.018000 0.018000" /></geometry></collision></link><link name="spine_03_x"><inertial><origin xyz="0.000000 0.000000 0.000000" rpy="0.000000 0.000000 0.000000" /><mass value="0.040000" /><inertia ixx="0.000010" ixy="0.0" ixz="0.0" iyy="0.000010" iyz="0.0" izz="0.000010" /></inertial><visual><origin xyz="0.000000 0.000000 0.000000" rpy="0.000000 0.000000 0.000000" /><geometry><sphere radius="0.009900" /></geometry></visual><visual><origin xyz="-0.000000 0.034734 0.000000" rpy="0.000000 -0.000000 1.570796" /><geometry><box size="0.069467 0.018000 0.018000" /></geometry></visual><visual><origin xyz="-0.007993 0.014636 -0.001037" rpy="0.000000 0.062121 2.070657" /><geometry><box size="0.033418 0.018000 0.018000" /></geometry></visual><visual><origin xyz="0.007993 0.014636 -0.001037" rpy="0.000000 0.062121 1.070936" /><geometry><box size="0.033418 0.018000 0.018000" /></geometry></visual><collision><origin xyz="0.000000 0.000000 0.000000" rpy="0.000000 0.000000 0.000000" /><geometry><sphere radius="0.009900" /></geometry></collision><collision><origin xyz="-0.000000 0.034734 0.000000" rpy="0.000000 -0.000000 1.570796" /><geometry><box size="0.069467 0.018000 0.018000" /></geometry></collision><collision><origin xyz="-0.007993 0.014636 -0.001037" rpy="0.000000 0.062121 2.070657" /><geometry><box size="0.033418 0.018000 0.018000" /></geometry></collision><collision><origin xyz="0.007993 0.014636 -0.001037" rpy="0.000000 0.062121 1.070936" /><geometry><box size="0.033418 0.018000 0.018000" /></geometry></collision></link><link name="neck_x"><inertial><origin xyz="0.000000 0.000000 0.000000" rpy="0.000000 0.000000 0.000000" /><mass value="0.020000" /><inertia ixx="0.000010" ixy="0.0" ixz="0.0" iyy="0.000010" iyz="0.0" izz="0.000010" /></inertial><visual><origin xyz="0.000000 0.000000 0.000000" rpy="0.000000 0.000000 0.000000" /><geometry><sphere radius="0.009900" /></geometry></visual><visual><origin xyz="0.000000 0.019683 0.000000" rpy="-0.000000 -0.000000 1.570796" /><geometry><box size="0.039366 0.018000 0.018000" /></geometry></visual><collision><origin xyz="0.000000 0.000000 0.000000" rpy="0.000000 0.000000 0.000000" /><geometry><sphere radius="0.009900" /></geometry></collision><collision><origin xyz="0.000000 0.019683 0.000000" rpy="-0.000000 -0.000000 1.570796" /><geometry><box size="0.039366 0.018000 0.018000" /></geometry></collision></link><link name="head_x"><inertial><origin xyz="0.000000 0.000000 0.000000" rpy="0.000000 0.000000 0.000000" /><mass value="0.020000" /><inertia ixx="0.000010" ixy="0.0" ixz="0.0" iyy="0.000010" iyz="0.0" izz="0.000010" /></inertial><visual><origin xyz="0.000000 0.000000 0.000000" rpy="0.000000 0.000000 0.000000" /><geometry><sphere radius="0.009900" /></geometry></visual><visual><origin xyz="0.011810 0.000000 0.000000" rpy="0.000000 0.000000 0.000000" /><geometry><box size="0.029524 0.018000 0.018000" /></geometry></visual><collision><origin xyz="0.000000 0.000000 0.000000" rpy="0.000000 0.000000 0.000000" /><geometry><sphere radius="0.009900" /></geometry></collision><collision><origin xyz="0.011810 0.000000 0.000000" rpy="0.000000 0.000000 0.000000" /><geometry><box size="0.029524 0.018000 0.018000" /></geometry></collision></link><link name="shoulder_r"><inertial><origin xyz="0.000000 0.000000 0.000000" rpy="0.000000 0.000000 0.000000" /><mass value="0.020000" /><inertia ixx="0.000010" ixy="0.0" ixz="0.0" iyy="0.000010" iyz="0.0" izz="0.000010" /></inertial><visual><origin xyz="0.000000 0.000000 0.000000" rpy="0.000000 0.000000 0.000000" /><geometry><sphere radius="0.009900" /></geometry></visual><visual><origin xyz="0.000000 0.023980 0.000000" rpy="0.000000 -0.000001 1.570796" /><geometry><box size="0.047960 0.018000 0.018000" /></geometry></visual><collision><origin xyz="0.000000 0.000000 0.000000" rpy="0.000000 0.000000 0.000000" /><geometry><sphere radius="0.009900" /></geometry></collision><collision><origin xyz="0.000000 0.023980 0.000000" rpy="0.000000 -0.000001 1.570796" /><geometry><box size="0.047960 0.018000 0.018000" /></geometry></collision></link><link name="arm_stretch_r"><inertial><origin xyz="0.000000 0.000000 0.000000" rpy="0.000000 0.000000 0.000000" /><mass value="0.020000" /><inertia ixx="0.000010" ixy="0.0" ixz="0.0" iyy="0.000010" iyz="0.0" izz="0.000010" /></inertial><visual><origin xyz="0.000000 0.000000 0.000000" rpy="0.000000 0.000000 0.000000" /><geometry><sphere radius="0.010955" /></geometry></visual><visual><origin xyz="0.000000 0.045270 0.000000" rpy="0.000000 -0.000001 1.570796" /><geometry><box size="0.090539 0.019919 0.019919" /></geometry></visual><collision><origin xyz="0.000000 0.000000 0.000000" rpy="0.000000 0.000000 0.000000" /><geometry><sphere radius="0.010955" /></geometry></collision><collision><origin xyz="0.000000 0.045270 0.000000" rpy="0.000000 -0.000001 1.570796" /><geometry><box size="0.090539 0.019919 0.019919" /></geometry></collision></link><link name="arm_twist_r"><inertial><origin xyz="0.000000 0.000000 0.000000" rpy="0.000000 0.000000 0.000000" /><mass value="0.020000" /><inertia ixx="0.000010" ixy="0.0" ixz="0.0" iyy="0.000010" iyz="0.0" izz="0.000010" /></inertial><visual><origin xyz="0.000000 0.000000 0.000000" rpy="0.000000 0.000000 0.000000" /><geometry><sphere radius="0.007700" /></geometry></visual><collision><origin xyz="0.000000 0.000000 0.000000" rpy="0.000000 0.000000 0.000000" /><geometry><sphere radius="0.007700" /></geometry></collision></link><link name="forearm_stretch_r"><inertial><origin xyz="0.000000 0.000000 0.000000" rpy="0.000000 0.000000 0.000000" /><mass value="0.030000" /><inertia ixx="0.000010" ixy="0.0" ixz="0.0" iyy="0.000010" iyz="0.0" izz="0.000010" /></inertial><visual><origin xyz="0.000000 0.000000 0.000000" rpy="0.000000 0.000000 0.000000" /><geometry><sphere radius="0.011156" /></geometry></visual><visual><origin xyz="-0.000000 0.023050 0.000000" rpy="-0.000000 -0.000002 1.570796" /><geometry><box size="0.046099 0.020284 0.020284" /></geometry></visual><visual><origin xyz="0.000000 0.046099 0.000000" rpy="0.000000 -0.000001 1.570796" /><geometry><box size="0.092199 0.020284 0.020284" /></geometry></visual><collision><origin xyz="0.000000 0.000000 0.000000" rpy="0.000000 0.000000 0.000000" /><geometry><sphere radius="0.011156" /></geometry></collision><collision><origin xyz="-0.000000 0.023050 0.000000" rpy="-0.000000 -0.000002 1.570796" /><geometry><box size="0.046099 0.020284 0.020284" /></geometry></collision><collision><origin xyz="0.000000 0.046099 0.000000" rpy="0.000000 -0.000001 1.570796" /><geometry><box size="0.092199 0.020284 0.020284" /></geometry></collision></link><link name="forearm_twist_r"><inertial><origin xyz="0.000000 0.000000 0.000000" rpy="0.000000 0.000000 0.000000" /><mass value="0.020000" /><inertia ixx="0.000010" ixy="0.0" ixz="0.0" iyy="0.000010" iyz="0.0" izz="0.000010" /></inertial><visual><origin xyz="0.000000 0.000000 0.000000" rpy="0.000000 0.000000 0.000000" /><geometry><sphere radius="0.007700" /></geometry></visual><visual><origin xyz="0.013830 0.000000 0.000000" rpy="0.000000 0.000000 0.000000" /><geometry><box size="0.034574 0.014000 0.014000" /></geometry></visual><collision><origin xyz="0.000000 0.000000 0.000000" rpy="0.000000 0.000000 0.000000" /><geometry><sphere radius="0.007700" /></geometry></collision><collision><origin xyz="0.013830 0.000000 0.000000" rpy="0.000000 0.000000 0.000000" /><geometry><box size="0.034574 0.014000 0.014000" /></geometry></collision></link><link name="hand_r"><inertial><origin xyz="0.000000 0.000000 0.000000" rpy="0.000000 0.000000 0.000000" /><mass value="0.060000" /><inertia ixx="0.000010" ixy="0.0" ixz="0.0" iyy="0.000010" iyz="0.0" izz="0.000010" /></inertial><visual><origin xyz="0.000000 0.000000 0.000000" rpy="0.000000 0.000000 0.000000" /><geometry><sphere radius="0.011156" /></geometry></visual><visual><origin xyz="-0.007036 0.010586 -0.004580" rpy="0.000000 0.345841 2.157381" /><geometry><box size="0.027022 0.020284 0.020284" /></geometry></visual><visual><origin xyz="-0.006532 0.010935 -0.000385" rpy="-0.000000 0.030210 2.109243" /><geometry><box size="0.025487 0.020284 0.020284" /></geometry></visual><visual><origin xyz="-0.000650 0.011507 -0.000104" rpy="-0.000000 0.009051 1.627180" /><geometry><box size="0.023052 0.020284 0.020284" /></geometry></visual><visual><origin xyz="0.004342 0.010752 -0.000090" rpy="0.000000 0.007785 1.187013" /><geometry><box size="0.023192 0.020284 0.020284" /></geometry></visual><visual><origin xyz="0.008400 0.008966 -0.000316" rpy="0.000000 0.025682 0.817961" /><geometry><box size="0.024580 0.020284 0.020284" /></geometry></visual><collision><origin xyz="0.000000 0.000000 0.000000" rpy="0.000000 0.000000 0.000000" /><geometry><sphere radius="0.011156" /></geometry></collision><collision><origin xyz="-0.007036 0.010586 -0.004580" rpy="0.000000 0.345841 2.157381" /><geometry><box size="0.027022 0.020284 0.020284" /></geometry></collision><collision><origin xyz="-0.006532 0.010935 -0.000385" rpy="-0.000000 0.030210 2.109243" /><geometry><box size="0.025487 0.020284 0.020284" /></geometry></collision><collision><origin xyz="-0.000650 0.011507 -0.000104" rpy="-0.000000 0.009051 1.627180" /><geometry><box size="0.023052 0.020284 0.020284" /></geometry></collision><collision><origin xyz="0.004342 0.010752 -0.000090" rpy="0.000000 0.007785 1.187013" /><geometry><box size="0.023192 0.020284 0.020284" /></geometry></collision><collision><origin xyz="0.008400 0.008966 -0.000316" rpy="0.000000 0.025682 0.817961" /><geometry><box size="0.024580 0.020284 0.020284" /></geometry></collision></link><link name="thumb1_r"><inertial><origin xyz="0.000000 0.000000 0.000000" rpy="0.000000 0.000000 0.000000" /><mass value="0.020000" /><inertia ixx="0.000010" ixy="0.0" ixz="0.0" iyy="0.000010" iyz="0.0" izz="0.000010" /></inertial><visual><origin xyz="0.000000 0.000000 0.000000" rpy="0.000000 0.000000 0.000000" /><geometry><sphere radius="0.005000" /></geometry></visual><visual><origin xyz="0.000000 0.013511 0.000000" rpy="0.000000 -0.000001 1.570795" /><geometry><box size="0.027022 0.009000 0.009000" /></geometry></visual><collision><origin xyz="0.000000 0.000000 0.000000" rpy="0.000000 0.000000 0.000000" /><geometry><sphere radius="0.005000" /></geometry></collision><collision><origin xyz="0.000000 0.013511 0.000000" rpy="0.000000 -0.000001 1.570795" /><geometry><box size="0.027022 0.009000 0.009000" /></geometry></collision></link><link name="thumb2_r"><inertial><origin xyz="0.000000 0.000000 0.000000" rpy="0.000000 0.000000 0.000000" /><mass value="0.020000" /><inertia ixx="0.000010" ixy="0.0" ixz="0.0" iyy="0.000010" iyz="0.0" izz="0.000010" /></inertial><visual><origin xyz="0.000000 0.000000 0.000000" rpy="0.000000 0.000000 0.000000" /><geometry><sphere radius="0.005000" /></geometry></visual><visual><origin xyz="0.000000 0.008081 0.000000" rpy="0.000000 -0.000000 1.570796" /><geometry><box size="0.016161 0.009000 0.009000" /></geometry></visual><collision><origin xyz="0.000000 0.000000 0.000000" rpy="0.000000 0.000000 0.000000" /><geometry><sphere radius="0.005000" /></geometry></collision><collision><origin xyz="0.000000 0.008081 0.000000" rpy="0.000000 -0.000000 1.570796" /><geometry><box size="0.016161 0.009000 0.009000" /></geometry></collision></link><link name="thumb3_r"><inertial><origin xyz="0.000000 0.000000 0.000000" rpy="0.000000 0.000000 0.000000" /><mass value="0.020000" /><inertia ixx="0.000010" ixy="0.0" ixz="0.0" iyy="0.000010" iyz="0.0" izz="0.000010" /></inertial><visual><origin xyz="0.000000 0.000000 0.000000" rpy="0.000000 0.000000 0.000000" /><geometry><sphere radius="0.005000" /></geometry></visual><visual><origin xyz="0.004848 0.000000 0.000000" rpy="0.000000 0.000000 0.000000" /><geometry><box size="0.012121 0.009000 0.009000" /></geometry></visual><collision><origin xyz="0.000000 0.000000 0.000000" rpy="0.000000 0.000000 0.000000" /><geometry><sphere radius="0.005000" /></geometry></collision><collision><origin xyz="0.004848 0.000000 0.000000" rpy="0.000000 0.000000 0.000000" /><geometry><box size="0.012121 0.009000 0.009000" /></geometry></collision></link><link name="index1_base_r"><inertial><origin xyz="0.000000 0.000000 0.000000" rpy="0.000000 0.000000 0.000000" /><mass value="0.020000" /><inertia ixx="0.000010" ixy="0.0" ixz="0.0" iyy="0.000010" iyz="0.0" izz="0.000010" /></inertial><visual><origin xyz="0.000000 0.000000 0.000000" rpy="0.000000 0.000000 0.000000" /><geometry><sphere radius="0.005000" /></geometry></visual><visual><origin xyz="0.000000 0.020916 -0.000000" rpy="-0.000000 0.000001 1.570796" /><geometry><box size="0.041832 0.009000 0.009000" /></geometry></visual><collision><origin xyz="0.000000 0.000000 0.000000" rpy="0.000000 0.000000 0.000000" /><geometry><sphere radius="0.005000" /></geometry></collision><collision><origin xyz="0.000000 0.020916 -0.000000" rpy="-0.000000 0.000001 1.570796" /><geometry><box size="0.041832 0.009000 0.009000" /></geometry></collision></link><link name="index1_r"><inertial><origin xyz="0.000000 0.000000 0.000000" rpy="0.000000 0.000000 0.000000" /><mass value="0.020000" /><inertia ixx="0.000010" ixy="0.0" ixz="0.0" iyy="0.000010" iyz="0.0" izz="0.000010" /></inertial><visual><origin xyz="0.000000 0.000000 0.000000" rpy="0.000000 0.000000 0.000000" /><geometry><sphere radius="0.005000" /></geometry></visual><visual><origin xyz="0.000000 0.007115 0.000000" rpy="0.000000 -0.000000 1.570796" /><geometry><box size="0.014229 0.009000 0.009000" /></geometry></visual><collision><origin xyz="0.000000 0.000000 0.000000" rpy="0.000000 0.000000 0.000000" /><geometry><sphere radius="0.005000" /></geometry></collision><collision><origin xyz="0.000000 0.007115 0.000000" rpy="0.000000 -0.000000 1.570796" /><geometry><box size="0.014229 0.009000 0.009000" /></geometry></collision></link><link name="index2_r"><inertial><origin xyz="0.000000 0.000000 0.000000" rpy="0.000000 0.000000 0.000000" /><mass value="0.020000" /><inertia ixx="0.000010" ixy="0.0" ixz="0.0" iyy="0.000010" iyz="0.0" izz="0.000010" /></inertial><visual><origin xyz="0.000000 0.000000 0.000000" rpy="0.000000 0.000000 0.000000" /><geometry><sphere radius="0.005000" /></geometry></visual><visual><origin xyz="0.000000 0.007146 0.000000" rpy="-0.000000 -0.000002 1.570796" /><geometry><box size="0.014291 0.009000 0.009000" /></geometry></visual><collision><origin xyz="0.000000 0.000000 0.000000" rpy="0.000000 0.000000 0.000000" /><geometry><sphere radius="0.005000" /></geometry></collision><collision><origin xyz="0.000000 0.007146 0.000000" rpy="-0.000000 -0.000002 1.570796" /><geometry><box size="0.014291 0.009000 0.009000" /></geometry></collision></link><link name="index3_r"><inertial><origin xyz="0.000000 0.000000 0.000000" rpy="0.000000 0.000000 0.000000" /><mass value="0.020000" /><inertia ixx="0.000010" ixy="0.0" ixz="0.0" iyy="0.000010" iyz="0.0" izz="0.000010" /></inertial><visual><origin xyz="0.000000 0.000000 0.000000" rpy="0.000000 0.000000 0.000000" /><geometry><sphere radius="0.005000" /></geometry></visual><visual><origin xyz="0.004287 0.000000 0.000000" rpy="0.000000 0.000000 0.000000" /><geometry><box size="0.010718 0.009000 0.009000" /></geometry></visual><collision><origin xyz="0.000000 0.000000 0.000000" rpy="0.000000 0.000000 0.000000" /><geometry><sphere radius="0.005000" /></geometry></collision><collision><origin xyz="0.004287 0.000000 0.000000" rpy="0.000000 0.000000 0.000000" /><geometry><box size="0.010718 0.009000 0.009000" /></geometry></collision></link><link name="middle1_base_r"><inertial><origin xyz="0.000000 0.000000 0.000000" rpy="0.000000 0.000000 0.000000" /><mass value="0.020000" /><inertia ixx="0.000010" ixy="0.0" ixz="0.0" iyy="0.000010" iyz="0.0" izz="0.000010" /></inertial><visual><origin xyz="0.000000 0.000000 0.000000" rpy="0.000000 0.000000 0.000000" /><geometry><sphere radius="0.005000" /></geometry></visual><visual><origin xyz="0.000000 0.021361 -0.000000" rpy="0.000000 0.000001 1.570796" /><geometry><box size="0.042722 0.009000 0.009000" /></geometry></visual><collision><origin xyz="0.000000 0.000000 0.000000" rpy="0.000000 0.000000 0.000000" /><geometry><sphere radius="0.005000" /></geometry></collision><collision><origin xyz="0.000000 0.021361 -0.000000" rpy="0.000000 0.000001 1.570796" /><geometry><box size="0.042722 0.009000 0.009000" /></geometry></collision></link><link name="middle1_r"><inertial><origin xyz="0.000000 0.000000 0.000000" rpy="0.000000 0.000000 0.000000" /><mass value="0.020000" /><inertia ixx="0.000010" ixy="0.0" ixz="0.0" iyy="0.000010" iyz="0.0" izz="0.000010" /></inertial><visual><origin xyz="0.000000 0.000000 0.000000" rpy="0.000000 0.000000 0.000000" /><geometry><sphere radius="0.005000" /></geometry></visual><visual><origin xyz="-0.000000 0.008689 0.000000" rpy="0.000000 -0.000000 1.570797" /><geometry><box size="0.017378 0.009000 0.009000" /></geometry></visual><collision><origin xyz="0.000000 0.000000 0.000000" rpy="0.000000 0.000000 0.000000" /><geometry><sphere radius="0.005000" /></geometry></collision><collision><origin xyz="-0.000000 0.008689 0.000000" rpy="0.000000 -0.000000 1.570797" /><geometry><box size="0.017378 0.009000 0.009000" /></geometry></collision></link><link name="middle2_r"><inertial><origin xyz="0.000000 0.000000 0.000000" rpy="0.000000 0.000000 0.000000" /><mass value="0.020000" /><inertia ixx="0.000010" ixy="0.0" ixz="0.0" iyy="0.000010" iyz="0.0" izz="0.000010" /></inertial><visual><origin xyz="0.000000 0.000000 0.000000" rpy="0.000000 0.000000 0.000000" /><geometry><sphere radius="0.005000" /></geometry></visual><visual><origin xyz="-0.000000 0.006444 0.000000" rpy="0.000000 -0.000000 1.570797" /><geometry><box size="0.012887 0.009000 0.009000" /></geometry></visual><collision><origin xyz="0.000000 0.000000 0.000000" rpy="0.000000 0.000000 0.000000" /><geometry><sphere radius="0.005000" /></geometry></collision><collision><origin xyz="-0.000000 0.006444 0.000000" rpy="0.000000 -0.000000 1.570797" /><geometry><box size="0.012887 0.009000 0.009000" /></geometry></collision></link><link name="middle3_r"><inertial><origin xyz="0.000000 0.000000 0.000000" rpy="0.000000 0.000000 0.000000" /><mass value="0.020000" /><inertia ixx="0.000010" ixy="0.0" ixz="0.0" iyy="0.000010" iyz="0.0" izz="0.000010" /></inertial><visual><origin xyz="0.000000 0.000000 0.000000" rpy="0.000000 0.000000 0.000000" /><geometry><sphere radius="0.005000" /></geometry></visual><visual><origin xyz="0.003866 0.000000 0.000000" rpy="0.000000 0.000000 0.000000" /><geometry><box size="0.009666 0.009000 0.009000" /></geometry></visual><collision><origin xyz="0.000000 0.000000 0.000000" rpy="0.000000 0.000000 0.000000" /><geometry><sphere radius="0.005000" /></geometry></collision><collision><origin xyz="0.003866 0.000000 0.000000" rpy="0.000000 0.000000 0.000000" /><geometry><box size="0.009666 0.009000 0.009000" /></geometry></collision></link><link name="ring1_base_r"><inertial><origin xyz="0.000000 0.000000 0.000000" rpy="0.000000 0.000000 0.000000" /><mass value="0.020000" /><inertia ixx="0.000010" ixy="0.0" ixz="0.0" iyy="0.000010" iyz="0.0" izz="0.000010" /></inertial><visual><origin xyz="0.000000 0.000000 0.000000" rpy="0.000000 0.000000 0.000000" /><geometry><sphere radius="0.005000" /></geometry></visual><visual><origin xyz="0.000000 0.021525 -0.000000" rpy="-0.000000 0.000001 1.570796" /><geometry><box size="0.043050 0.009000 0.009000" /></geometry></visual><collision><origin xyz="0.000000 0.000000 0.000000" rpy="0.000000 0.000000 0.000000" /><geometry><sphere radius="0.005000" /></geometry></collision><collision><origin xyz="0.000000 0.021525 -0.000000" rpy="-0.000000 0.000001 1.570796" /><geometry><box size="0.043050 0.009000 0.009000" /></geometry></collision></link><link name="ring1_r"><inertial><origin xyz="0.000000 0.000000 0.000000" rpy="0.000000 0.000000 0.000000" /><mass value="0.020000" /><inertia ixx="0.000010" ixy="0.0" ixz="0.0" iyy="0.000010" iyz="0.0" izz="0.000010" /></inertial><visual><origin xyz="0.000000 0.000000 0.000000" rpy="0.000000 0.000000 0.000000" /><geometry><sphere radius="0.005000" /></geometry></visual><visual><origin xyz="-0.000000 0.006810 0.000000" rpy="-0.000000 -0.000004 1.570797" /><geometry><box size="0.013621 0.009000 0.009000" /></geometry></visual><collision><origin xyz="0.000000 0.000000 0.000000" rpy="0.000000 0.000000 0.000000" /><geometry><sphere radius="0.005000" /></geometry></collision><collision><origin xyz="-0.000000 0.006810 0.000000" rpy="-0.000000 -0.000004 1.570797" /><geometry><box size="0.013621 0.009000 0.009000" /></geometry></collision></link><link name="ring2_r"><inertial><origin xyz="0.000000 0.000000 0.000000" rpy="0.000000 0.000000 0.000000" /><mass value="0.020000" /><inertia ixx="0.000010" ixy="0.0" ixz="0.0" iyy="0.000010" iyz="0.0" izz="0.000010" /></inertial><visual><origin xyz="0.000000 0.000000 0.000000" rpy="0.000000 0.000000 0.000000" /><geometry><sphere radius="0.005000" /></geometry></visual><visual><origin xyz="-0.000000 0.005963 0.000000" rpy="0.000000 -0.000002 1.570797" /><geometry><box size="0.011927 0.009000 0.009000" /></geometry></visual><collision><origin xyz="0.000000 0.000000 0.000000" rpy="0.000000 0.000000 0.000000" /><geometry><sphere radius="0.005000" /></geometry></collision><collision><origin xyz="-0.000000 0.005963 0.000000" rpy="0.000000 -0.000002 1.570797" /><geometry><box size="0.011927 0.009000 0.009000" /></geometry></collision></link><link name="ring3_r"><inertial><origin xyz="0.000000 0.000000 0.000000" rpy="0.000000 0.000000 0.000000" /><mass value="0.020000" /><inertia ixx="0.000010" ixy="0.0" ixz="0.0" iyy="0.000010" iyz="0.0" izz="0.000010" /></inertial><visual><origin xyz="0.000000 0.000000 0.000000" rpy="0.000000 0.000000 0.000000" /><geometry><sphere radius="0.005000" /></geometry></visual><visual><origin xyz="0.003600 0.000000 0.000000" rpy="0.000000 0.000000 0.000000" /><geometry><box size="0.009000 0.009000 0.009000" /></geometry></visual><collision><origin xyz="0.000000 0.000000 0.000000" rpy="0.000000 0.000000 0.000000" /><geometry><sphere radius="0.005000" /></geometry></collision><collision><origin xyz="0.003600 0.000000 0.000000" rpy="0.000000 0.000000 0.000000" /><geometry><box size="0.009000 0.009000 0.009000" /></geometry></collision></link><link name="pinky1_base_r"><inertial><origin xyz="0.000000 0.000000 0.000000" rpy="0.000000 0.000000 0.000000" /><mass value="0.020000" /><inertia ixx="0.000010" ixy="0.0" ixz="0.0" iyy="0.000010" iyz="0.0" izz="0.000010" /></inertial><visual><origin xyz="0.000000 0.000000 0.000000" rpy="0.000000 0.000000 0.000000" /><geometry><sphere radius="0.005000" /></geometry></visual><visual><origin xyz="0.000000 0.021623 0.000000" rpy="0.000000 -0.000000 1.570796" /><geometry><box size="0.043247 0.009000 0.009000" /></geometry></visual><collision><origin xyz="0.000000 0.000000 0.000000" rpy="0.000000 0.000000 0.000000" /><geometry><sphere radius="0.005000" /></geometry></collision><collision><origin xyz="0.000000 0.021623 0.000000" rpy="0.000000 -0.000000 1.570796" /><geometry><box size="0.043247 0.009000 0.009000" /></geometry></collision></link><link name="pinky1_r"><inertial><origin xyz="0.000000 0.000000 0.000000" rpy="0.000000 0.000000 0.000000" /><mass value="0.020000" /><inertia ixx="0.000010" ixy="0.0" ixz="0.0" iyy="0.000010" iyz="0.0" izz="0.000010" /></inertial><visual><origin xyz="0.000000 0.000000 0.000000" rpy="0.000000 0.000000 0.000000" /><geometry><sphere radius="0.005000" /></geometry></visual><visual><origin xyz="0.000000 0.003910 0.000000" rpy="0.000000 -0.000000 1.570794" /><geometry><box size="0.007821 0.009000 0.009000" /></geometry></visual><collision><origin xyz="0.000000 0.000000 0.000000" rpy="0.000000 0.000000 0.000000" /><geometry><sphere radius="0.005000" /></geometry></collision><collision><origin xyz="0.000000 0.003910 0.000000" rpy="0.000000 -0.000000 1.570794" /><geometry><box size="0.007821 0.009000 0.009000" /></geometry></collision></link><link name="pinky2_r"><inertial><origin xyz="0.000000 0.000000 0.000000" rpy="0.000000 0.000000 0.000000" /><mass value="0.020000" /><inertia ixx="0.000010" ixy="0.0" ixz="0.0" iyy="0.000010" iyz="0.0" izz="0.000010" /></inertial><visual><origin xyz="0.000000 0.000000 0.000000" rpy="0.000000 0.000000 0.000000" /><geometry><sphere radius="0.005000" /></geometry></visual><visual><origin xyz="-0.000000 0.003863 0.000000" rpy="0.000000 -0.000000 1.570798" /><geometry><box size="0.007725 0.009000 0.009000" /></geometry></visual><collision><origin xyz="0.000000 0.000000 0.000000" rpy="0.000000 0.000000 0.000000" /><geometry><sphere radius="0.005000" /></geometry></collision><collision><origin xyz="-0.000000 0.003863 0.000000" rpy="0.000000 -0.000000 1.570798" /><geometry><box size="0.007725 0.009000 0.009000" /></geometry></collision></link><link name="pinky3_r"><inertial><origin xyz="0.000000 0.000000 0.000000" rpy="0.000000 0.000000 0.000000" /><mass value="0.020000" /><inertia ixx="0.000010" ixy="0.0" ixz="0.0" iyy="0.000010" iyz="0.0" izz="0.000010" /></inertial><visual><origin xyz="0.000000 0.000000 0.000000" rpy="0.000000 0.000000 0.000000" /><geometry><sphere radius="0.005000" /></geometry></visual><visual><origin xyz="0.003600 0.000000 0.000000" rpy="0.000000 0.000000 0.000000" /><geometry><box size="0.009000 0.009000 0.009000" /></geometry></visual><collision><origin xyz="0.000000 0.000000 0.000000" rpy="0.000000 0.000000 0.000000" /><geometry><sphere radius="0.005000" /></geometry></collision><collision><origin xyz="0.003600 0.000000 0.000000" rpy="0.000000 0.000000 0.000000" /><geometry><box size="0.009000 0.009000 0.009000" /></geometry></collision></link><link name="shoulder_l"><inertial><origin xyz="0.000000 0.000000 0.000000" rpy="0.000000 0.000000 0.000000" /><mass value="0.020000" /><inertia ixx="0.000010" ixy="0.0" ixz="0.0" iyy="0.000010" iyz="0.0" izz="0.000010" /></inertial><visual><origin xyz="0.000000 0.000000 0.000000" rpy="0.000000 0.000000 0.000000" /><geometry><sphere radius="0.009900" /></geometry></visual><visual><origin xyz="0.000000 0.023980 0.000000" rpy="0.000000 -0.000000 1.570796" /><geometry><box size="0.047960 0.018000 0.018000" /></geometry></visual><collision><origin xyz="0.000000 0.000000 0.000000" rpy="0.000000 0.000000 0.000000" /><geometry><sphere radius="0.009900" /></geometry></collision><collision><origin xyz="0.000000 0.023980 0.000000" rpy="0.000000 -0.000000 1.570796" /><geometry><box size="0.047960 0.018000 0.018000" /></geometry></collision></link><link name="arm_stretch_l"><inertial><origin xyz="0.000000 0.000000 0.000000" rpy="0.000000 0.000000 0.000000" /><mass value="0.020000" /><inertia ixx="0.000010" ixy="0.0" ixz="0.0" iyy="0.000010" iyz="0.0" izz="0.000010" /></inertial><visual><origin xyz="0.000000 0.000000 0.000000" rpy="0.000000 0.000000 0.000000" /><geometry><sphere radius="0.010955" /></geometry></visual><visual><origin xyz="0.000000 0.045270 0.000000" rpy="0.000000 -0.000000 1.570796" /><geometry><box size="0.090539 0.019919 0.019919" /></geometry></visual><collision><origin xyz="0.000000 0.000000 0.000000" rpy="0.000000 0.000000 0.000000" /><geometry><sphere radius="0.010955" /></geometry></collision><collision><origin xyz="0.000000 0.045270 0.000000" rpy="0.000000 -0.000000 1.570796" /><geometry><box size="0.090539 0.019919 0.019919" /></geometry></collision></link><link name="arm_twist_l"><inertial><origin xyz="0.000000 0.000000 0.000000" rpy="0.000000 0.000000 0.000000" /><mass value="0.020000" /><inertia ixx="0.000010" ixy="0.0" ixz="0.0" iyy="0.000010" iyz="0.0" izz="0.000010" /></inertial><visual><origin xyz="0.000000 0.000000 0.000000" rpy="0.000000 0.000000 0.000000" /><geometry><sphere radius="0.007700" /></geometry></visual><collision><origin xyz="0.000000 0.000000 0.000000" rpy="0.000000 0.000000 0.000000" /><geometry><sphere radius="0.007700" /></geometry></collision></link><link name="forearm_stretch_l"><inertial><origin xyz="0.000000 0.000000 0.000000" rpy="0.000000 0.000000 0.000000" /><mass value="0.030000" /><inertia ixx="0.000010" ixy="0.0" ixz="0.0" iyy="0.000010" iyz="0.0" izz="0.000010" /></inertial><visual><origin xyz="0.000000 0.000000 0.000000" rpy="0.000000 0.000000 0.000000" /><geometry><sphere radius="0.011156" /></geometry></visual><visual><origin xyz="0.000000 0.023050 0.000000" rpy="0.000000 -0.000001 1.570796" /><geometry><box size="0.046099 0.020284 0.020284" /></geometry></visual><visual><origin xyz="0.000000 0.046099 0.000000" rpy="0.000000 -0.000000 1.570796" /><geometry><box size="0.092199 0.020284 0.020284" /></geometry></visual><collision><origin xyz="0.000000 0.000000 0.000000" rpy="0.000000 0.000000 0.000000" /><geometry><sphere radius="0.011156" /></geometry></collision><collision><origin xyz="0.000000 0.023050 0.000000" rpy="0.000000 -0.000001 1.570796" /><geometry><box size="0.046099 0.020284 0.020284" /></geometry></collision><collision><origin xyz="0.000000 0.046099 0.000000" rpy="0.000000 -0.000000 1.570796" /><geometry><box size="0.092199 0.020284 0.020284" /></geometry></collision></link><link name="forearm_twist_l"><inertial><origin xyz="0.000000 0.000000 0.000000" rpy="0.000000 0.000000 0.000000" /><mass value="0.020000" /><inertia ixx="0.000010" ixy="0.0" ixz="0.0" iyy="0.000010" iyz="0.0" izz="0.000010" /></inertial><visual><origin xyz="0.000000 0.000000 0.000000" rpy="0.000000 0.000000 0.000000" /><geometry><sphere radius="0.007700" /></geometry></visual><visual><origin xyz="0.013830 0.000000 0.000000" rpy="0.000000 0.000000 0.000000" /><geometry><box size="0.034574 0.014000 0.014000" /></geometry></visual><collision><origin xyz="0.000000 0.000000 0.000000" rpy="0.000000 0.000000 0.000000" /><geometry><sphere radius="0.007700" /></geometry></collision><collision><origin xyz="0.013830 0.000000 0.000000" rpy="0.000000 0.000000 0.000000" /><geometry><box size="0.034574 0.014000 0.014000" /></geometry></collision></link><link name="hand_l"><inertial><origin xyz="0.000000 0.000000 0.000000" rpy="0.000000 0.000000 0.000000" /><mass value="0.060000" /><inertia ixx="0.000010" ixy="0.0" ixz="0.0" iyy="0.000010" iyz="0.0" izz="0.000010" /></inertial><visual><origin xyz="0.000000 0.000000 0.000000" rpy="0.000000 0.000000 0.000000" /><geometry><sphere radius="0.011156" /></geometry></visual><visual><origin xyz="0.007036 0.010586 -0.004580" rpy="0.000000 0.345841 0.984212" /><geometry><box size="0.027022 0.020284 0.020284" /></geometry></visual><visual><origin xyz="0.006532 0.010935 -0.000385" rpy="0.000000 0.030210 1.032348" /><geometry><box size="0.025487 0.020284 0.020284" /></geometry></visual><visual><origin xyz="0.000650 0.011507 -0.000104" rpy="0.000000 0.009052 1.514414" /><geometry><box size="0.023052 0.020284 0.020284" /></geometry></visual><visual><origin xyz="-0.004342 0.010752 -0.000090" rpy="0.000000 0.007783 1.954580" /><geometry><box size="0.023192 0.020284 0.020284" /></geometry></visual><visual><origin xyz="-0.008400 0.008966 -0.000316" rpy="0.000000 0.025682 2.323631" /><geometry><box size="0.024580 0.020284 0.020284" /></geometry></visual><collision><origin xyz="0.000000 0.000000 0.000000" rpy="0.000000 0.000000 0.000000" /><geometry><sphere radius="0.011156" /></geometry></collision><collision><origin xyz="0.007036 0.010586 -0.004580" rpy="0.000000 0.345841 0.984212" /><geometry><box size="0.027022 0.020284 0.020284" /></geometry></collision><collision><origin xyz="0.006532 0.010935 -0.000385" rpy="0.000000 0.030210 1.032348" /><geometry><box size="0.025487 0.020284 0.020284" /></geometry></collision><collision><origin xyz="0.000650 0.011507 -0.000104" rpy="0.000000 0.009052 1.514414" /><geometry><box size="0.023052 0.020284 0.020284" /></geometry></collision><collision><origin xyz="-0.004342 0.010752 -0.000090" rpy="0.000000 0.007783 1.954580" /><geometry><box size="0.023192 0.020284 0.020284" /></geometry></collision><collision><origin xyz="-0.008400 0.008966 -0.000316" rpy="0.000000 0.025682 2.323631" /><geometry><box size="0.024580 0.020284 0.020284" /></geometry></collision></link><link name="thumb1_l"><inertial><origin xyz="0.000000 0.000000 0.000000" rpy="0.000000 0.000000 0.000000" /><mass value="0.020000" /><inertia ixx="0.000010" ixy="0.0" ixz="0.0" iyy="0.000010" iyz="0.0" izz="0.000010" /></inertial><visual><origin xyz="0.000000 0.000000 0.000000" rpy="0.000000 0.000000 0.000000" /><geometry><sphere radius="0.005000" /></geometry></visual><visual><origin xyz="0.000000 0.013511 0.000000" rpy="0.000000 -0.000000 1.570795" /><geometry><box size="0.027022 0.009000 0.009000" /></geometry></visual><collision><origin xyz="0.000000 0.000000 0.000000" rpy="0.000000 0.000000 0.000000" /><geometry><sphere radius="0.005000" /></geometry></collision><collision><origin xyz="0.000000 0.013511 0.000000" rpy="0.000000 -0.000000 1.570795" /><geometry><box size="0.027022 0.009000 0.009000" /></geometry></collision></link><link name="thumb2_l"><inertial><origin xyz="0.000000 0.000000 0.000000" rpy="0.000000 0.000000 0.000000" /><mass value="0.020000" /><inertia ixx="0.000010" ixy="0.0" ixz="0.0" iyy="0.000010" iyz="0.0" izz="0.000010" /></inertial><visual><origin xyz="0.000000 0.000000 0.000000" rpy="0.000000 0.000000 0.000000" /><geometry><sphere radius="0.005000" /></geometry></visual><visual><origin xyz="-0.000000 0.008081 -0.000000" rpy="-0.000000 0.000002 1.570798" /><geometry><box size="0.016161 0.009000 0.009000" /></geometry></visual><collision><origin xyz="0.000000 0.000000 0.000000" rpy="0.000000 0.000000 0.000000" /><geometry><sphere radius="0.005000" /></geometry></collision><collision><origin xyz="-0.000000 0.008081 -0.000000" rpy="-0.000000 0.000002 1.570798" /><geometry><box size="0.016161 0.009000 0.009000" /></geometry></collision></link><link name="thumb3_l"><inertial><origin xyz="0.000000 0.000000 0.000000" rpy="0.000000 0.000000 0.000000" /><mass value="0.020000" /><inertia ixx="0.000010" ixy="0.0" ixz="0.0" iyy="0.000010" iyz="0.0" izz="0.000010" /></inertial><visual><origin xyz="0.000000 0.000000 0.000000" rpy="0.000000 0.000000 0.000000" /><geometry><sphere radius="0.005000" /></geometry></visual><visual><origin xyz="0.004848 0.000000 0.000000" rpy="0.000000 0.000000 0.000000" /><geometry><box size="0.012121 0.009000 0.009000" /></geometry></visual><collision><origin xyz="0.000000 0.000000 0.000000" rpy="0.000000 0.000000 0.000000" /><geometry><sphere radius="0.005000" /></geometry></collision><collision><origin xyz="0.004848 0.000000 0.000000" rpy="0.000000 0.000000 0.000000" /><geometry><box size="0.012121 0.009000 0.009000" /></geometry></collision></link><link name="index1_base_l"><inertial><origin xyz="0.000000 0.000000 0.000000" rpy="0.000000 0.000000 0.000000" /><mass value="0.020000" /><inertia ixx="0.000010" ixy="0.0" ixz="0.0" iyy="0.000010" iyz="0.0" izz="0.000010" /></inertial><visual><origin xyz="0.000000 0.000000 0.000000" rpy="0.000000 0.000000 0.000000" /><geometry><sphere radius="0.005000" /></geometry></visual><visual><origin xyz="0.000000 0.020916 -0.000000" rpy="0.000000 0.000001 1.570796" /><geometry><box size="0.041832 0.009000 0.009000" /></geometry></visual><collision><origin xyz="0.000000 0.000000 0.000000" rpy="0.000000 0.000000 0.000000" /><geometry><sphere radius="0.005000" /></geometry></collision><collision><origin xyz="0.000000 0.020916 -0.000000" rpy="0.000000 0.000001 1.570796" /><geometry><box size="0.041832 0.009000 0.009000" /></geometry></collision></link><link name="index1_l"><inertial><origin xyz="0.000000 0.000000 0.000000" rpy="0.000000 0.000000 0.000000" /><mass value="0.020000" /><inertia ixx="0.000010" ixy="0.0" ixz="0.0" iyy="0.000010" iyz="0.0" izz="0.000010" /></inertial><visual><origin xyz="0.000000 0.000000 0.000000" rpy="0.000000 0.000000 0.000000" /><geometry><sphere radius="0.005000" /></geometry></visual><visual><origin xyz="0.000000 0.007115 0.000000" rpy="-0.000000 -0.000002 1.570796" /><geometry><box size="0.014229 0.009000 0.009000" /></geometry></visual><collision><origin xyz="0.000000 0.000000 0.000000" rpy="0.000000 0.000000 0.000000" /><geometry><sphere radius="0.005000" /></geometry></collision><collision><origin xyz="0.000000 0.007115 0.000000" rpy="-0.000000 -0.000002 1.570796" /><geometry><box size="0.014229 0.009000 0.009000" /></geometry></collision></link><link name="index2_l"><inertial><origin xyz="0.000000 0.000000 0.000000" rpy="0.000000 0.000000 0.000000" /><mass value="0.020000" /><inertia ixx="0.000010" ixy="0.0" ixz="0.0" iyy="0.000010" iyz="0.0" izz="0.000010" /></inertial><visual><origin xyz="0.000000 0.000000 0.000000" rpy="0.000000 0.000000 0.000000" /><geometry><sphere radius="0.005000" /></geometry></visual><visual><origin xyz="0.000000 0.007146 0.000000" rpy="-0.000000 -0.000004 1.570795" /><geometry><box size="0.014291 0.009000 0.009000" /></geometry></visual><collision><origin xyz="0.000000 0.000000 0.000000" rpy="0.000000 0.000000 0.000000" /><geometry><sphere radius="0.005000" /></geometry></collision><collision><origin xyz="0.000000 0.007146 0.000000" rpy="-0.000000 -0.000004 1.570795" /><geometry><box size="0.014291 0.009000 0.009000" /></geometry></collision></link><link name="index3_l"><inertial><origin xyz="0.000000 0.000000 0.000000" rpy="0.000000 0.000000 0.000000" /><mass value="0.020000" /><inertia ixx="0.000010" ixy="0.0" ixz="0.0" iyy="0.000010" iyz="0.0" izz="0.000010" /></inertial><visual><origin xyz="0.000000 0.000000 0.000000" rpy="0.000000 0.000000 0.000000" /><geometry><sphere radius="0.005000" /></geometry></visual><visual><origin xyz="0.004287 0.000000 0.000000" rpy="0.000000 0.000000 0.000000" /><geometry><box size="0.010718 0.009000 0.009000" /></geometry></visual><collision><origin xyz="0.000000 0.000000 0.000000" rpy="0.000000 0.000000 0.000000" /><geometry><sphere radius="0.005000" /></geometry></collision><collision><origin xyz="0.004287 0.000000 0.000000" rpy="0.000000 0.000000 0.000000" /><geometry><box size="0.010718 0.009000 0.009000" /></geometry></collision></link><link name="middle1_base_l"><inertial><origin xyz="0.000000 0.000000 0.000000" rpy="0.000000 0.000000 0.000000" /><mass value="0.020000" /><inertia ixx="0.000010" ixy="0.0" ixz="0.0" iyy="0.000010" iyz="0.0" izz="0.000010" /></inertial><visual><origin xyz="0.000000 0.000000 0.000000" rpy="0.000000 0.000000 0.000000" /><geometry><sphere radius="0.005000" /></geometry></visual><visual><origin xyz="0.000000 0.021361 0.000000" rpy="0.000000 -0.000000 1.570796" /><geometry><box size="0.042722 0.009000 0.009000" /></geometry></visual><collision><origin xyz="0.000000 0.000000 0.000000" rpy="0.000000 0.000000 0.000000" /><geometry><sphere radius="0.005000" /></geometry></collision><collision><origin xyz="0.000000 0.021361 0.000000" rpy="0.000000 -0.000000 1.570796" /><geometry><box size="0.042722 0.009000 0.009000" /></geometry></collision></link><link name="middle1_l"><inertial><origin xyz="0.000000 0.000000 0.000000" rpy="0.000000 0.000000 0.000000" /><mass value="0.020000" /><inertia ixx="0.000010" ixy="0.0" ixz="0.0" iyy="0.000010" iyz="0.0" izz="0.000010" /></inertial><visual><origin xyz="0.000000 0.000000 0.000000" rpy="0.000000 0.000000 0.000000" /><geometry><sphere radius="0.005000" /></geometry></visual><visual><origin xyz="0.000000 0.008689 -0.000000" rpy="0.000000 0.000002 1.570796" /><geometry><box size="0.017378 0.009000 0.009000" /></geometry></visual><collision><origin xyz="0.000000 0.000000 0.000000" rpy="0.000000 0.000000 0.000000" /><geometry><sphere radius="0.005000" /></geometry></collision><collision><origin xyz="0.000000 0.008689 -0.000000" rpy="0.000000 0.000002 1.570796" /><geometry><box size="0.017378 0.009000 0.009000" /></geometry></collision></link><link name="middle2_l"><inertial><origin xyz="0.000000 0.000000 0.000000" rpy="0.000000 0.000000 0.000000" /><mass value="0.020000" /><inertia ixx="0.000010" ixy="0.0" ixz="0.0" iyy="0.000010" iyz="0.0" izz="0.000010" /></inertial><visual><origin xyz="0.000000 0.000000 0.000000" rpy="0.000000 0.000000 0.000000" /><geometry><sphere radius="0.005000" /></geometry></visual><visual><origin xyz="-0.000000 0.006444 -0.000000" rpy="0.000000 0.000002 1.570797" /><geometry><box size="0.012887 0.009000 0.009000" /></geometry></visual><collision><origin xyz="0.000000 0.000000 0.000000" rpy="0.000000 0.000000 0.000000" /><geometry><sphere radius="0.005000" /></geometry></collision><collision><origin xyz="-0.000000 0.006444 -0.000000" rpy="0.000000 0.000002 1.570797" /><geometry><box size="0.012887 0.009000 0.009000" /></geometry></collision></link><link name="middle3_l"><inertial><origin xyz="0.000000 0.000000 0.000000" rpy="0.000000 0.000000 0.000000" /><mass value="0.020000" /><inertia ixx="0.000010" ixy="0.0" ixz="0.0" iyy="0.000010" iyz="0.0" izz="0.000010" /></inertial><visual><origin xyz="0.000000 0.000000 0.000000" rpy="0.000000 0.000000 0.000000" /><geometry><sphere radius="0.005000" /></geometry></visual><visual><origin xyz="0.003866 0.000000 0.000000" rpy="0.000000 0.000000 0.000000" /><geometry><box size="0.009666 0.009000 0.009000" /></geometry></visual><collision><origin xyz="0.000000 0.000000 0.000000" rpy="0.000000 0.000000 0.000000" /><geometry><sphere radius="0.005000" /></geometry></collision><collision><origin xyz="0.003866 0.000000 0.000000" rpy="0.000000 0.000000 0.000000" /><geometry><box size="0.009666 0.009000 0.009000" /></geometry></collision></link><link name="ring1_base_l"><inertial><origin xyz="0.000000 0.000000 0.000000" rpy="0.000000 0.000000 0.000000" /><mass value="0.020000" /><inertia ixx="0.000010" ixy="0.0" ixz="0.0" iyy="0.000010" iyz="0.0" izz="0.000010" /></inertial><visual><origin xyz="0.000000 0.000000 0.000000" rpy="0.000000 0.000000 0.000000" /><geometry><sphere radius="0.005000" /></geometry></visual><visual><origin xyz="-0.000000 0.021525 -0.000000" rpy="0.000000 0.000001 1.570796" /><geometry><box size="0.043050 0.009000 0.009000" /></geometry></visual><collision><origin xyz="0.000000 0.000000 0.000000" rpy="0.000000 0.000000 0.000000" /><geometry><sphere radius="0.005000" /></geometry></collision><collision><origin xyz="-0.000000 0.021525 -0.000000" rpy="0.000000 0.000001 1.570796" /><geometry><box size="0.043050 0.009000 0.009000" /></geometry></collision></link><link name="ring1_l"><inertial><origin xyz="0.000000 0.000000 0.000000" rpy="0.000000 0.000000 0.000000" /><mass value="0.020000" /><inertia ixx="0.000010" ixy="0.0" ixz="0.0" iyy="0.000010" iyz="0.0" izz="0.000010" /></inertial><visual><origin xyz="0.000000 0.000000 0.000000" rpy="0.000000 0.000000 0.000000" /><geometry><sphere radius="0.005000" /></geometry></visual><visual><origin xyz="-0.000000 0.006810 0.000000" rpy="0.000000 -0.000000 1.570797" /><geometry><box size="0.013621 0.009000 0.009000" /></geometry></visual><collision><origin xyz="0.000000 0.000000 0.000000" rpy="0.000000 0.000000 0.000000" /><geometry><sphere radius="0.005000" /></geometry></collision><collision><origin xyz="-0.000000 0.006810 0.000000" rpy="0.000000 -0.000000 1.570797" /><geometry><box size="0.013621 0.009000 0.009000" /></geometry></collision></link><link name="ring2_l"><inertial><origin xyz="0.000000 0.000000 0.000000" rpy="0.000000 0.000000 0.000000" /><mass value="0.020000" /><inertia ixx="0.000010" ixy="0.0" ixz="0.0" iyy="0.000010" iyz="0.0" izz="0.000010" /></inertial><visual><origin xyz="0.000000 0.000000 0.000000" rpy="0.000000 0.000000 0.000000" /><geometry><sphere radius="0.005000" /></geometry></visual><visual><origin xyz="0.000000 0.005963 0.000000" rpy="0.000000 -0.000000 1.570796" /><geometry><box size="0.011927 0.009000 0.009000" /></geometry></visual><collision><origin xyz="0.000000 0.000000 0.000000" rpy="0.000000 0.000000 0.000000" /><geometry><sphere radius="0.005000" /></geometry></collision><collision><origin xyz="0.000000 0.005963 0.000000" rpy="0.000000 -0.000000 1.570796" /><geometry><box size="0.011927 0.009000 0.009000" /></geometry></collision></link><link name="ring3_l"><inertial><origin xyz="0.000000 0.000000 0.000000" rpy="0.000000 0.000000 0.000000" /><mass value="0.020000" /><inertia ixx="0.000010" ixy="0.0" ixz="0.0" iyy="0.000010" iyz="0.0" izz="0.000010" /></inertial><visual><origin xyz="0.000000 0.000000 0.000000" rpy="0.000000 0.000000 0.000000" /><geometry><sphere radius="0.005000" /></geometry></visual><visual><origin xyz="0.003600 0.000000 0.000000" rpy="0.000000 0.000000 0.000000" /><geometry><box size="0.009000 0.009000 0.009000" /></geometry></visual><collision><origin xyz="0.000000 0.000000 0.000000" rpy="0.000000 0.000000 0.000000" /><geometry><sphere radius="0.005000" /></geometry></collision><collision><origin xyz="0.003600 0.000000 0.000000" rpy="0.000000 0.000000 0.000000" /><geometry><box size="0.009000 0.009000 0.009000" /></geometry></collision></link><link name="pinky1_base_l"><inertial><origin xyz="0.000000 0.000000 0.000000" rpy="0.000000 0.000000 0.000000" /><mass value="0.020000" /><inertia ixx="0.000010" ixy="0.0" ixz="0.0" iyy="0.000010" iyz="0.0" izz="0.000010" /></inertial><visual><origin xyz="0.000000 0.000000 0.000000" rpy="0.000000 0.000000 0.000000" /><geometry><sphere radius="0.005000" /></geometry></visual><visual><origin xyz="-0.000000 0.021623 -0.000000" rpy="-0.000000 0.000001 1.570797" /><geometry><box size="0.043247 0.009000 0.009000" /></geometry></visual><collision><origin xyz="0.000000 0.000000 0.000000" rpy="0.000000 0.000000 0.000000" /><geometry><sphere radius="0.005000" /></geometry></collision><collision><origin xyz="-0.000000 0.021623 -0.000000" rpy="-0.000000 0.000001 1.570797" /><geometry><box size="0.043247 0.009000 0.009000" /></geometry></collision></link><link name="pinky1_l"><inertial><origin xyz="0.000000 0.000000 0.000000" rpy="0.000000 0.000000 0.000000" /><mass value="0.020000" /><inertia ixx="0.000010" ixy="0.0" ixz="0.0" iyy="0.000010" iyz="0.0" izz="0.000010" /></inertial><visual><origin xyz="0.000000 0.000000 0.000000" rpy="0.000000 0.000000 0.000000" /><geometry><sphere radius="0.005000" /></geometry></visual><visual><origin xyz="-0.000000 0.003910 0.000000" rpy="0.000000 -0.000000 1.570798" /><geometry><box size="0.007820 0.009000 0.009000" /></geometry></visual><collision><origin xyz="0.000000 0.000000 0.000000" rpy="0.000000 0.000000 0.000000" /><geometry><sphere radius="0.005000" /></geometry></collision><collision><origin xyz="-0.000000 0.003910 0.000000" rpy="0.000000 -0.000000 1.570798" /><geometry><box size="0.007820 0.009000 0.009000" /></geometry></collision></link><link name="pinky2_l"><inertial><origin xyz="0.000000 0.000000 0.000000" rpy="0.000000 0.000000 0.000000" /><mass value="0.020000" /><inertia ixx="0.000010" ixy="0.0" ixz="0.0" iyy="0.000010" iyz="0.0" izz="0.000010" /></inertial><visual><origin xyz="0.000000 0.000000 0.000000" rpy="0.000000 0.000000 0.000000" /><geometry><sphere radius="0.005000" /></geometry></visual><visual><origin xyz="0.000000 0.003863 0.000000" rpy="0.000000 -0.000000 1.570795" /><geometry><box size="0.007725 0.009000 0.009000" /></geometry></visual><collision><origin xyz="0.000000 0.000000 0.000000" rpy="0.000000 0.000000 0.000000" /><geometry><sphere radius="0.005000" /></geometry></collision><collision><origin xyz="0.000000 0.003863 0.000000" rpy="0.000000 -0.000000 1.570795" /><geometry><box size="0.007725 0.009000 0.009000" /></geometry></collision></link><link name="pinky3_l"><inertial><origin xyz="0.000000 0.000000 0.000000" rpy="0.000000 0.000000 0.000000" /><mass value="0.020000" /><inertia ixx="0.000010" ixy="0.0" ixz="0.0" iyy="0.000010" iyz="0.0" izz="0.000010" /></inertial><visual><origin xyz="0.000000 0.000000 0.000000" rpy="0.000000 0.000000 0.000000" /><geometry><sphere radius="0.005000" /></geometry></visual><visual><origin xyz="0.003600 0.000000 0.000000" rpy="0.000000 0.000000 0.000000" /><geometry><box size="0.009000 0.009000 0.009000" /></geometry></visual><collision><origin xyz="0.000000 0.000000 0.000000" rpy="0.000000 0.000000 0.000000" /><geometry><sphere radius="0.005000" /></geometry></collision><collision><origin xyz="0.003600 0.000000 0.000000" rpy="0.000000 0.000000 0.000000" /><geometry><box size="0.009000 0.009000 0.009000" /></geometry></collision></link><link name="thigh_stretch_l"><inertial><origin xyz="0.000000 0.000000 0.000000" rpy="0.000000 0.000000 0.000000" /><mass value="0.041351" /><inertia ixx="0.000010" ixy="0.0" ixz="0.0" iyy="0.000048" iyz="0.0" izz="0.000048" /></inertial><visual><origin xyz="0.000000 0.000000 0.000000" rpy="0.000000 0.000000 0.000000" /><geometry><sphere radius="0.017108" /></geometry></visual><visual><origin xyz="-0.000000 0.064804 -0.000000" rpy="-0.000000 0.000000 1.570796" /><geometry><box size="0.129607 0.031106 0.031106" /></geometry></visual><collision><origin xyz="0.000000 0.000000 0.000000" rpy="0.000000 0.000000 0.000000" /><geometry><sphere radius="0.017108" /></geometry></collision><collision><origin xyz="-0.000000 0.064804 -0.000000" rpy="-0.000000 0.000000 1.570796" /><geometry><box size="0.129607 0.031106 0.031106" /></geometry></collision></link><link name="thigh_twist_l"><inertial><origin xyz="0.000000 0.000000 0.000000" rpy="0.000000 0.000000 0.000000" /><mass value="0.020000" /><inertia ixx="0.000010" ixy="0.0" ixz="0.0" iyy="0.000010" iyz="0.0" izz="0.000010" /></inertial><visual><origin xyz="0.000000 0.000000 0.000000" rpy="0.000000 0.000000 0.000000" /><geometry><sphere radius="0.008800" /></geometry></visual><collision><origin xyz="0.000000 0.000000 0.000000" rpy="0.000000 0.000000 0.000000" /><geometry><sphere radius="0.008800" /></geometry></collision></link><link name="leg_stretch_l"><inertial><origin xyz="0.000000 0.000000 0.000000" rpy="0.000000 0.000000 0.000000" /><mass value="0.057288" /><inertia ixx="0.000010" ixy="0.0" ixz="0.0" iyy="0.000055" iyz="0.0" izz="0.000055" /></inertial><visual><origin xyz="0.000000 0.000000 0.000000" rpy="0.000000 0.000000 0.000000" /><geometry><sphere radius="0.017140" /></geometry></visual><visual><origin xyz="0.000000 0.064923 0.000000" rpy="0.000000 -0.000000 1.570796" /><geometry><box size="0.129847 0.031163 0.031163" /></geometry></visual><visual><origin xyz="-0.000000 0.032462 0.000000" rpy="-0.000000 -0.000000 1.570796" /><geometry><box size="0.064923 0.031163 0.031163" /></geometry></visual><collision><origin xyz="0.000000 0.000000 0.000000" rpy="0.000000 0.000000 0.000000" /><geometry><sphere radius="0.017140" /></geometry></collision><collision><origin xyz="0.000000 0.064923 0.000000" rpy="0.000000 -0.000000 1.570796" /><geometry><box size="0.129847 0.031163 0.031163" /></geometry></collision><collision><origin xyz="-0.000000 0.032462 0.000000" rpy="-0.000000 -0.000000 1.570796" /><geometry><box size="0.064923 0.031163 0.031163" /></geometry></collision></link><link name="foot_l"><inertial><origin xyz="0.000000 0.000000 0.000000" rpy="0.000000 0.000000 0.000000" /><mass value="0.025738" /><inertia ixx="0.000010" ixy="0.0" ixz="0.0" iyy="0.000010" iyz="0.0" izz="0.000010" /></inertial><visual><origin xyz="0.000000 0.000000 0.000000" rpy="0.000000 0.000000 0.000000" /><geometry><sphere radius="0.017140" /></geometry></visual><visual><origin xyz="-0.000000 0.032411 0.000000" rpy="0.000000 -0.000000 1.570796" /><geometry><box size="0.064823 0.031163 0.031163" /></geometry></visual><collision><origin xyz="0.000000 0.000000 0.000000" rpy="0.000000 0.000000 0.000000" /><geometry><sphere radius="0.017140" /></geometry></collision><collision><origin xyz="-0.000000 0.032411 0.000000" rpy="0.000000 -0.000000 1.570796" /><geometry><box size="0.064823 0.031163 0.031163" /></geometry></collision></link><link name="toes_01_l"><inertial><origin xyz="0.000000 0.000000 0.000000" rpy="0.000000 0.000000 0.000000" /><mass value="0.020000" /><inertia ixx="0.000010" ixy="0.0" ixz="0.0" iyy="0.000010" iyz="0.0" izz="0.000010" /></inertial><visual><origin xyz="0.000000 0.000000 0.000000" rpy="0.000000 0.000000 0.000000" /><geometry><sphere radius="0.008800" /></geometry></visual><visual><origin xyz="0.019447 0.000000 0.000000" rpy="0.000000 0.000000 0.000000" /><geometry><box size="0.048617 0.016000 0.016000" /></geometry></visual><collision><origin xyz="0.000000 0.000000 0.000000" rpy="0.000000 0.000000 0.000000" /><geometry><sphere radius="0.008800" /></geometry></collision><collision><origin xyz="0.019447 0.000000 0.000000" rpy="0.000000 0.000000 0.000000" /><geometry><box size="0.048617 0.016000 0.016000" /></geometry></collision></link><link name="leg_twist_l"><inertial><origin xyz="0.000000 0.000000 0.000000" rpy="0.000000 0.000000 0.000000" /><mass value="0.020000" /><inertia ixx="0.000010" ixy="0.0" ixz="0.0" iyy="0.000010" iyz="0.0" izz="0.000010" /></inertial><visual><origin xyz="0.000000 0.000000 0.000000" rpy="0.000000 0.000000 0.000000" /><geometry><sphere radius="0.008800" /></geometry></visual><visual><origin xyz="0.019477 0.000000 0.000000" rpy="0.000000 0.000000 0.000000" /><geometry><box size="0.048693 0.016000 0.016000" /></geometry></visual><collision><origin xyz="0.000000 0.000000 0.000000" rpy="0.000000 0.000000 0.000000" /><geometry><sphere radius="0.008800" /></geometry></collision><collision><origin xyz="0.019477 0.000000 0.000000" rpy="0.000000 0.000000 0.000000" /><geometry><box size="0.048693 0.016000 0.016000" /></geometry></collision></link><link name="thigh_stretch_r"><inertial><origin xyz="0.000000 0.000000 0.000000" rpy="0.000000 0.000000 0.000000" /><mass value="0.041351" /><inertia ixx="0.000010" ixy="0.0" ixz="0.0" iyy="0.000048" iyz="0.0" izz="0.000048" /></inertial><visual><origin xyz="0.000000 0.000000 0.000000" rpy="0.000000 0.000000 0.000000" /><geometry><sphere radius="0.017108" /></geometry></visual><visual><origin xyz="-0.000000 0.064804 0.000000" rpy="0.000000 -0.000000 1.570796" /><geometry><box size="0.129607 0.031106 0.031106" /></geometry></visual><collision><origin xyz="0.000000 0.000000 0.000000" rpy="0.000000 0.000000 0.000000" /><geometry><sphere radius="0.017108" /></geometry></collision><collision><origin xyz="-0.000000 0.064804 0.000000" rpy="0.000000 -0.000000 1.570796" /><geometry><box size="0.129607 0.031106 0.031106" /></geometry></collision></link><link name="thigh_twist_r"><inertial><origin xyz="0.000000 0.000000 0.000000" rpy="0.000000 0.000000 0.000000" /><mass value="0.020000" /><inertia ixx="0.000010" ixy="0.0" ixz="0.0" iyy="0.000010" iyz="0.0" izz="0.000010" /></inertial><visual><origin xyz="0.000000 0.000000 0.000000" rpy="0.000000 0.000000 0.000000" /><geometry><sphere radius="0.008800" /></geometry></visual><collision><origin xyz="0.000000 0.000000 0.000000" rpy="0.000000 0.000000 0.000000" /><geometry><sphere radius="0.008800" /></geometry></collision></link><link name="leg_stretch_r"><inertial><origin xyz="0.000000 0.000000 0.000000" rpy="0.000000 0.000000 0.000000" /><mass value="0.057287" /><inertia ixx="0.000010" ixy="0.0" ixz="0.0" iyy="0.000055" iyz="0.0" izz="0.000055" /></inertial><visual><origin xyz="0.000000 0.000000 0.000000" rpy="0.000000 0.000000 0.000000" /><geometry><sphere radius="0.017140" /></geometry></visual><visual><origin xyz="0.000000 0.064923 -0.000000" rpy="-0.000000 0.000000 1.570796" /><geometry><box size="0.129847 0.031163 0.031163" /></geometry></visual><visual><origin xyz="-0.000000 0.032462 -0.000000" rpy="0.000000 0.000000 1.570796" /><geometry><box size="0.064923 0.031163 0.031163" /></geometry></visual><collision><origin xyz="0.000000 0.000000 0.000000" rpy="0.000000 0.000000 0.000000" /><geometry><sphere radius="0.017140" /></geometry></collision><collision><origin xyz="0.000000 0.064923 -0.000000" rpy="-0.000000 0.000000 1.570796" /><geometry><box size="0.129847 0.031163 0.031163" /></geometry></collision><collision><origin xyz="-0.000000 0.032462 -0.000000" rpy="0.000000 0.000000 1.570796" /><geometry><box size="0.064923 0.031163 0.031163" /></geometry></collision></link><link name="foot_r"><inertial><origin xyz="0.000000 0.000000 0.000000" rpy="0.000000 0.000000 0.000000" /><mass value="0.025738" /><inertia ixx="0.000010" ixy="0.0" ixz="0.0" iyy="0.000010" iyz="0.0" izz="0.000010" /></inertial><visual><origin xyz="0.000000 0.000000 0.000000" rpy="0.000000 0.000000 0.000000" /><geometry><sphere radius="0.017140" /></geometry></visual><visual><origin xyz="-0.000000 0.032411 -0.000000" rpy="-0.000000 0.000000 1.570796" /><geometry><box size="0.064823 0.031163 0.031163" /></geometry></visual><collision><origin xyz="0.000000 0.000000 0.000000" rpy="0.000000 0.000000 0.000000" /><geometry><sphere radius="0.017140" /></geometry></collision><collision><origin xyz="-0.000000 0.032411 -0.000000" rpy="-0.000000 0.000000 1.570796" /><geometry><box size="0.064823 0.031163 0.031163" /></geometry></collision></link><link name="toes_01_r"><inertial><origin xyz="0.000000 0.000000 0.000000" rpy="0.000000 0.000000 0.000000" /><mass value="0.020000" /><inertia ixx="0.000010" ixy="0.0" ixz="0.0" iyy="0.000010" iyz="0.0" izz="0.000010" /></inertial><visual><origin xyz="0.000000 0.000000 0.000000" rpy="0.000000 0.000000 0.000000" /><geometry><sphere radius="0.008800" /></geometry></visual><visual><origin xyz="0.019447 0.000000 0.000000" rpy="0.000000 0.000000 0.000000" /><geometry><box size="0.048617 0.016000 0.016000" /></geometry></visual><collision><origin xyz="0.000000 0.000000 0.000000" rpy="0.000000 0.000000 0.000000" /><geometry><sphere radius="0.008800" /></geometry></collision><collision><origin xyz="0.019447 0.000000 0.000000" rpy="0.000000 0.000000 0.000000" /><geometry><box size="0.048617 0.016000 0.016000" /></geometry></collision></link><link name="leg_twist_r"><inertial><origin xyz="0.000000 0.000000 0.000000" rpy="0.000000 0.000000 0.000000" /><mass value="0.020000" /><inertia ixx="0.000010" ixy="0.0" ixz="0.0" iyy="0.000010" iyz="0.0" izz="0.000010" /></inertial><visual><origin xyz="0.000000 0.000000 0.000000" rpy="0.000000 0.000000 0.000000" /><geometry><sphere radius="0.008800" /></geometry></visual><visual><origin xyz="0.019477 0.000000 0.000000" rpy="0.000000 0.000000 0.000000" /><geometry><box size="0.048692 0.016000 0.016000" /></geometry></visual><collision><origin xyz="0.000000 0.000000 0.000000" rpy="0.000000 0.000000 0.000000" /><geometry><sphere radius="0.008800" /></geometry></collision><collision><origin xyz="0.019477 0.000000 0.000000" rpy="0.000000 0.000000 0.000000" /><geometry><box size="0.048692 0.016000 0.016000" /></geometry></collision></link><joint name="spine_01_x" type="revolute"><parent link="root_x" /><child link="spine_01_x" /><origin xyz="-0.000000 0.060500 -0.034518" rpy="-0.074748 0.000003 0.000000" /><axis xyz="0.0 1.0 0.0" /><limit lower="-0.700000" upper="0.700000" effort="50.0" velocity="4.0" /><dynamics damping="1.0" friction="0.05" /></joint><joint name="spine_02_x" type="revolute"><parent link="spine_01_x" /><child link="spine_02_x" /><origin xyz="-0.000000 0.067965 -0.000000" rpy="0.352639 0.000000 -0.000000" /><axis xyz="0.0 1.0 0.0" /><limit lower="-0.700000" upper="0.700000" effort="50.0" velocity="4.0" /><dynamics damping="1.0" friction="0.05" /></joint><joint name="spine_03_x" type="revolute"><parent link="spine_02_x" /><child link="spine_03_x" /><origin xyz="0.000000 0.069307 -0.000000" rpy="-0.284678 -0.000000 0.000000" /><axis xyz="0.0 1.0 0.0" /><limit lower="-0.700000" upper="0.700000" effort="50.0" velocity="4.0" /><dynamics damping="1.0" friction="0.05" /></joint><joint name="neck_x" type="revolute"><parent link="spine_03_x" /><child link="neck_x" /><origin xyz="-0.000000 0.069467 0.000000" rpy="0.227851 0.000000 -0.000000" /><axis xyz="0.0 1.0 0.0" /><limit lower="-0.700000" upper="0.700000" effort="50.0" velocity="4.0" /><dynamics damping="1.0" friction="0.05" /></joint><joint name="head_x" type="revolute"><parent link="neck_x" /><child link="head_x" /><origin xyz="0.000000 0.039366 0.000000" rpy="-0.221063 0.000000 0.000000" /><axis xyz="0.0 1.0 0.0" /><limit lower="-0.700000" upper="0.700000" effort="50.0" velocity="4.0" /><dynamics damping="1.0" friction="0.05" /></joint><joint name="shoulder_r" type="revolute"><parent link="spine_03_x" /><child link="shoulder_r" /><origin xyz="-0.015987 0.029273 -0.002075" rpy="0.000033 1.565935 1.570829" /><axis xyz="0.0 0.0 1.0" /><limit lower="-1.800000" upper="1.800000" effort="50.0" velocity="4.0" /><dynamics damping="1.0" friction="0.05" /></joint><joint name="arm_stretch_r" type="revolute"><parent link="shoulder_r" /><child link="arm_stretch_r" /><origin xyz="0.000000 0.047960 0.000000" rpy="-0.903337 -0.052030 -0.039675" /><axis xyz="0.0 1.0 0.0" /><limit lower="-1.800000" upper="1.800000" effort="50.0" velocity="4.0" /><dynamics damping="1.0" friction="0.05" /></joint><joint name="arm_twist_r" type="revolute"><parent link="arm_stretch_r" /><child link="arm_twist_r" /><origin xyz="0.000000 0.000000 0.000000" rpy="-0.000000 0.000000 0.000000" /><axis xyz="1.0 0.0 0.0" /><limit lower="-1.200000" upper="1.200000" effort="50.0" velocity="4.0" /><dynamics damping="1.0" friction="0.05" /></joint><joint name="forearm_stretch_r" type="revolute"><parent link="arm_stretch_r" /><child link="forearm_stretch_r" /><origin xyz="0.000000 0.090539 0.000000" rpy="-0.000047 -0.000173 0.264238" /><axis xyz="0.0 1.0 0.0" /><limit lower="-1.800000" upper="1.800000" effort="50.0" velocity="4.0" /><dynamics damping="1.0" friction="0.05" /></joint><joint name="forearm_twist_r" type="revolute"><parent link="forearm_stretch_r" /><child link="forearm_twist_r" /><origin xyz="-0.000000 0.046099 0.000000" rpy="-0.000000 0.161409 -0.000000" /><axis xyz="1.0 0.0 0.0" /><limit lower="-1.200000" upper="1.200000" effort="50.0" velocity="4.0" /><dynamics damping="1.0" friction="0.05" /></joint><joint name="hand_r" type="revolute"><parent link="forearm_stretch_r" /><child link="hand_r" /><origin xyz="0.000000 0.092199 0.000000" rpy="-0.032273 0.160228 -0.122099" /><axis xyz="0.0 0.0 1.0" /><limit lower="-1.800000" upper="1.800000" effort="50.0" velocity="4.0" /><dynamics damping="1.0" friction="0.05" /></joint><joint name="thumb1_r" type="revolute"><parent link="hand_r" /><child link="thumb1_r" /><origin xyz="-0.014072 0.021172 -0.009160" rpy="-1.356043 -1.216472 1.928880" /><axis xyz="0.0 1.0 0.0" /><limit lower="-1.200000" upper="1.200000" effort="50.0" velocity="4.0" /><dynamics damping="1.0" friction="0.05" /></joint><joint name="thumb2_r" type="revolute"><parent link="thumb1_r" /><child link="thumb2_r" /><origin xyz="0.000000 0.027022 0.000000" rpy="0.069783 0.348140 0.462812" /><axis xyz="0.0 0.0 1.0" /><limit lower="-1.500000" upper="1.000000" effort="50.0" velocity="4.0" /><dynamics damping="1.0" friction="0.05" /></joint><joint name="thumb3_r" type="revolute"><parent link="thumb2_r" /><child link="thumb3_r" /><origin xyz="0.000000 0.016161 0.000000" rpy="0.068860 -0.078468 -0.099512" /><axis xyz="0.0 0.0 1.0" /><limit lower="-1.500000" upper="1.000000" effort="50.0" velocity="4.0" /><dynamics damping="1.0" friction="0.05" /></joint><joint name="index1_base_r" type="revolute"><parent link="hand_r" /><child link="index1_base_r" /><origin xyz="-0.013064 0.021871 -0.000770" rpy="0.046371 -0.000000 0.093843" /><axis xyz="0.0 0.0 1.0" /><limit lower="-0.450000" upper="0.450000" effort="50.0" velocity="4.0" /><dynamics damping="1.0" friction="0.05" /></joint><joint name="index1_r" type="revolute"><parent link="index1_base_r" /><child link="index1_r" /><origin xyz="0.000000 0.041832 -0.000000" rpy="-0.018911 -0.000823 0.094256" /><axis xyz="0.0 0.0 1.0" /><limit lower="0.000000" upper="1.600000" effort="50.0" velocity="4.0" /><dynamics damping="1.0" friction="0.05" /></joint><joint name="index2_r" type="revolute"><parent link="index1_r" /><child link="index2_r" /><origin xyz="0.000000 0.014229 0.000000" rpy="0.015109 -0.000840 -0.132563" /><axis xyz="0.0 0.0 1.0" /><limit lower="0.000000" upper="1.600000" effort="50.0" velocity="4.0" /><dynamics damping="1.0" friction="0.05" /></joint><joint name="index3_r" type="revolute"><parent link="index2_r" /><child link="index3_r" /><origin xyz="0.000000 0.014291 0.000000" rpy="0.043239 -0.002465 0.001454" /><axis xyz="0.0 0.0 1.0" /><limit lower="0.000000" upper="1.600000" effort="50.0" velocity="4.0" /><dynamics damping="1.0" friction="0.05" /></joint><joint name="middle1_base_r" type="revolute"><parent link="hand_r" /><child link="middle1_base_r" /><origin xyz="-0.001299 0.023015 -0.000209" rpy="0.004885 0.000000 -0.030411" /><axis xyz="0.0 0.0 1.0" /><limit lower="-0.450000" upper="0.450000" effort="50.0" velocity="4.0" /><dynamics damping="1.0" friction="0.05" /></joint><joint name="middle1_r" type="revolute"><parent link="middle1_base_r" /><child link="middle1_r" /><origin xyz="0.000000 0.042722 -0.000000" rpy="-0.034946 -0.001128 -0.006071" /><axis xyz="0.0 0.0 1.0" /><limit lower="0.000000" upper="1.600000" effort="50.0" velocity="4.0" /><dynamics damping="1.0" friction="0.05" /></joint><joint name="middle2_r" type="revolute"><parent link="middle1_r" /><child link="middle2_r" /><origin xyz="-0.000000 0.017378 0.000000" rpy="-0.079009 -0.007453 -0.057353" /><axis xyz="0.0 0.0 1.0" /><limit lower="0.000000" upper="1.600000" effort="50.0" velocity="4.0" /><dynamics damping="1.0" friction="0.05" /></joint><joint name="middle3_r" type="revolute"><parent link="middle2_r" /><child link="middle3_r" /><origin xyz="-0.000000 0.012887 0.000000" rpy="-0.050882 -0.004692 0.002267" /><axis xyz="0.0 0.0 1.0" /><limit lower="0.000000" upper="1.600000" effort="50.0" velocity="4.0" /><dynamics damping="1.0" friction="0.05" /></joint><joint name="ring1_base_r" type="revolute"><parent link="hand_r" /><child link="ring1_base_r" /><origin xyz="0.008684 0.021505 -0.000181" rpy="-0.052344 0.000000 -0.122979" /><axis xyz="0.0 0.0 1.0" /><limit lower="-0.450000" upper="0.450000" effort="50.0" velocity="4.0" /><dynamics damping="1.0" friction="0.05" /></joint><joint name="ring1_r" type="revolute"><parent link="ring1_base_r" /><child link="ring1_r" /><origin xyz="0.000000 0.043050 -0.000000" rpy="-0.036781 -0.016557 -0.140266" /><axis xyz="0.0 0.0 1.0" /><limit lower="0.000000" upper="1.600000" effort="50.0" velocity="4.0" /><dynamics damping="1.0" friction="0.05" /></joint><joint name="ring2_r" type="revolute"><parent link="ring1_r" /><child link="ring2_r" /><origin xyz="-0.000000 0.013621 0.000000" rpy="-0.131790 -0.045046 -0.064214" /><axis xyz="0.0 0.0 1.0" /><limit lower="0.000000" upper="1.600000" effort="50.0" velocity="4.0" /><dynamics damping="1.0" friction="0.05" /></joint><joint name="ring3_r" type="revolute"><parent link="ring2_r" /><child link="ring3_r" /><origin xyz="-0.000000 0.011927 0.000000" rpy="0.019436 0.006209 0.021339" /><axis xyz="0.0 0.0 1.0" /><limit lower="0.000000" upper="1.600000" effort="50.0" velocity="4.0" /><dynamics damping="1.0" friction="0.05" /></joint><joint name="pinky1_base_r" type="revolute"><parent link="hand_r" /><child link="pinky1_base_r" /><origin xyz="0.016800 0.017932 -0.000631" rpy="-0.137207 -0.000000 -0.242037" /><axis xyz="0.0 0.0 1.0" /><limit lower="-0.450000" upper="0.450000" effort="50.0" velocity="4.0" /><dynamics damping="1.0" friction="0.05" /></joint><joint name="pinky1_r" type="revolute"><parent link="pinky1_base_r" /><child link="pinky1_r" /><origin xyz="0.000000 0.043247 0.000000" rpy="-0.175045 -0.149489 -0.319301" /><axis xyz="0.0 0.0 1.0" /><limit lower="0.000000" upper="1.600000" effort="50.0" velocity="4.0" /><dynamics damping="1.0" friction="0.05" /></joint><joint name="pinky2_r" type="revolute"><parent link="pinky1_r" /><child link="pinky2_r" /><origin xyz="0.000000 0.007821 0.000000" rpy="-0.117003 -0.072529 0.016065" /><axis xyz="0.0 0.0 1.0" /><limit lower="0.000000" upper="1.600000" effort="50.0" velocity="4.0" /><dynamics damping="1.0" friction="0.05" /></joint><joint name="pinky3_r" type="revolute"><parent link="pinky2_r" /><child link="pinky3_r" /><origin xyz="-0.000000 0.007725 0.000000" rpy="-0.035197 -0.021263 0.013498" /><axis xyz="0.0 0.0 1.0" /><limit lower="0.000000" upper="1.600000" effort="50.0" velocity="4.0" /><dynamics damping="1.0" friction="0.05" /></joint><joint name="shoulder_l" type="revolute"><parent link="spine_03_x" /><child link="shoulder_l" /><origin xyz="0.015987 0.029273 -0.002075" rpy="-0.000093 -1.565935 -1.570703" /><axis xyz="0.0 0.0 1.0" /><limit lower="-1.800000" upper="1.800000" effort="50.0" velocity="4.0" /><dynamics damping="1.0" friction="0.05" /></joint><joint name="arm_stretch_l" type="revolute"><parent link="shoulder_l" /><child link="arm_stretch_l" /><origin xyz="0.000000 0.047960 0.000000" rpy="-0.903354 0.052291 0.039342" /><axis xyz="0.0 1.0 0.0" /><limit lower="-1.800000" upper="1.800000" effort="50.0" velocity="4.0" /><dynamics damping="1.0" friction="0.05" /></joint><joint name="arm_twist_l" type="revolute"><parent link="arm_stretch_l" /><child link="arm_twist_l" /><origin xyz="0.000000 0.000000 -0.000000" rpy="-0.000000 -0.000000 -0.000000" /><axis xyz="1.0 0.0 0.0" /><limit lower="-1.200000" upper="1.200000" effort="50.0" velocity="4.0" /><dynamics damping="1.0" friction="0.05" /></joint><joint name="forearm_stretch_l" type="revolute"><parent link="arm_stretch_l" /><child link="forearm_stretch_l" /><origin xyz="0.000000 0.090539 0.000000" rpy="0.000064 -0.000235 -0.264238" /><axis xyz="0.0 1.0 0.0" /><limit lower="-1.800000" upper="1.800000" effort="50.0" velocity="4.0" /><dynamics damping="1.0" friction="0.05" /></joint><joint name="forearm_twist_l" type="revolute"><parent link="forearm_stretch_l" /><child link="forearm_twist_l" /><origin xyz="0.000000 0.046099 0.000000" rpy="-0.000000 -0.161408 0.000000" /><axis xyz="1.0 0.0 0.0" /><limit lower="-1.200000" upper="1.200000" effort="50.0" velocity="4.0" /><dynamics damping="1.0" friction="0.05" /></joint><joint name="hand_l" type="revolute"><parent link="forearm_stretch_l" /><child link="hand_l" /><origin xyz="0.000000 0.092199 0.000000" rpy="-0.032274 -0.160228 0.122099" /><axis xyz="0.0 0.0 1.0" /><limit lower="-1.800000" upper="1.800000" effort="50.0" velocity="4.0" /><dynamics damping="1.0" friction="0.05" /></joint><joint name="thumb1_l" type="revolute"><parent link="hand_l" /><child link="thumb1_l" /><origin xyz="0.014072 0.021172 -0.009160" rpy="-1.356045 1.216473 -1.928883" /><axis xyz="0.0 1.0 0.0" /><limit lower="-1.200000" upper="1.200000" effort="50.0" velocity="4.0" /><dynamics damping="1.0" friction="0.05" /></joint><joint name="thumb2_l" type="revolute"><parent link="thumb1_l" /><child link="thumb2_l" /><origin xyz="0.000000 0.027022 0.000000" rpy="0.069783 -0.348140 -0.462812" /><axis xyz="0.0 0.0 1.0" /><limit lower="-1.500000" upper="1.000000" effort="50.0" velocity="4.0" /><dynamics damping="1.0" friction="0.05" /></joint><joint name="thumb3_l" type="revolute"><parent link="thumb2_l" /><child link="thumb3_l" /><origin xyz="-0.000000 0.016161 -0.000000" rpy="0.068861 0.078468 0.099511" /><axis xyz="0.0 0.0 1.0" /><limit lower="-1.500000" upper="1.000000" effort="50.0" velocity="4.0" /><dynamics damping="1.0" friction="0.05" /></joint><joint name="index1_base_l" type="revolute"><parent link="hand_l" /><child link="index1_base_l" /><origin xyz="0.013064 0.021871 -0.000770" rpy="0.046371 0.000000 -0.093843" /><axis xyz="0.0 0.0 1.0" /><limit lower="-0.450000" upper="0.450000" effort="50.0" velocity="4.0" /><dynamics damping="1.0" friction="0.05" /></joint><joint name="index1_l" type="revolute"><parent link="index1_base_l" /><child link="index1_l" /><origin xyz="0.000000 0.041832 -0.000000" rpy="-0.018912 0.000823 -0.094255" /><axis xyz="0.0 0.0 1.0" /><limit lower="0.000000" upper="1.600000" effort="50.0" velocity="4.0" /><dynamics damping="1.0" friction="0.05" /></joint><joint name="index2_l" type="revolute"><parent link="index1_l" /><child link="index2_l" /><origin xyz="0.000000 0.014229 0.000000" rpy="0.015110 0.000839 0.132563" /><axis xyz="0.0 0.0 1.0" /><limit lower="0.000000" upper="1.600000" effort="50.0" velocity="4.0" /><dynamics damping="1.0" friction="0.05" /></joint><joint name="index3_l" type="revolute"><parent link="index2_l" /><child link="index3_l" /><origin xyz="0.000000 0.014291 0.000000" rpy="0.043239 0.002466 -0.001454" /><axis xyz="0.0 0.0 1.0" /><limit lower="0.000000" upper="1.600000" effort="50.0" velocity="4.0" /><dynamics damping="1.0" friction="0.05" /></joint><joint name="middle1_base_l" type="revolute"><parent link="hand_l" /><child link="middle1_base_l" /><origin xyz="0.001299 0.023015 -0.000209" rpy="0.004885 -0.000000 0.030411" /><axis xyz="0.0 0.0 1.0" /><limit lower="-0.450000" upper="0.450000" effort="50.0" velocity="4.0" /><dynamics damping="1.0" friction="0.05" /></joint><joint name="middle1_l" type="revolute"><parent link="middle1_base_l" /><child link="middle1_l" /><origin xyz="0.000000 0.042722 0.000000" rpy="-0.034946 0.001127 0.006071" /><axis xyz="0.0 0.0 1.0" /><limit lower="0.000000" upper="1.600000" effort="50.0" velocity="4.0" /><dynamics damping="1.0" friction="0.05" /></joint><joint name="middle2_l" type="revolute"><parent link="middle1_l" /><child link="middle2_l" /><origin xyz="0.000000 0.017378 -0.000000" rpy="-0.079008 0.007453 0.057353" /><axis xyz="0.0 0.0 1.0" /><limit lower="0.000000" upper="1.600000" effort="50.0" velocity="4.0" /><dynamics damping="1.0" friction="0.05" /></joint><joint name="middle3_l" type="revolute"><parent link="middle2_l" /><child link="middle3_l" /><origin xyz="-0.000000 0.012887 -0.000000" rpy="-0.050883 0.004692 -0.002267" /><axis xyz="0.0 0.0 1.0" /><limit lower="0.000000" upper="1.600000" effort="50.0" velocity="4.0" /><dynamics damping="1.0" friction="0.05" /></joint><joint name="ring1_base_l" type="revolute"><parent link="hand_l" /><child link="ring1_base_l" /><origin xyz="-0.008684 0.021505 -0.000181" rpy="-0.052344 -0.000000 0.122979" /><axis xyz="0.0 0.0 1.0" /><limit lower="-0.450000" upper="0.450000" effort="50.0" velocity="4.0" /><dynamics damping="1.0" friction="0.05" /></joint><joint name="ring1_l" type="revolute"><parent link="ring1_base_l" /><child link="ring1_l" /><origin xyz="-0.000000 0.043050 -0.000000" rpy="-0.036781 0.016557 0.140266" /><axis xyz="0.0 0.0 1.0" /><limit lower="0.000000" upper="1.600000" effort="50.0" velocity="4.0" /><dynamics damping="1.0" friction="0.05" /></joint><joint name="ring2_l" type="revolute"><parent link="ring1_l" /><child link="ring2_l" /><origin xyz="-0.000000 0.013621 0.000000" rpy="-0.131789 0.045045 0.064214" /><axis xyz="0.0 0.0 1.0" /><limit lower="0.000000" upper="1.600000" effort="50.0" velocity="4.0" /><dynamics damping="1.0" friction="0.05" /></joint><joint name="ring3_l" type="revolute"><parent link="ring2_l" /><child link="ring3_l" /><origin xyz="0.000000 0.011927 0.000000" rpy="0.019436 -0.006208 -0.021339" /><axis xyz="0.0 0.0 1.0" /><limit lower="0.000000" upper="1.600000" effort="50.0" velocity="4.0" /><dynamics damping="1.0" friction="0.05" /></joint><joint name="pinky1_base_l" type="revolute"><parent link="hand_l" /><child link="pinky1_base_l" /><origin xyz="-0.016800 0.017932 -0.000631" rpy="-0.137206 -0.000000 0.242037" /><axis xyz="0.0 0.0 1.0" /><limit lower="-0.450000" upper="0.450000" effort="50.0" velocity="4.0" /><dynamics damping="1.0" friction="0.05" /></joint><joint name="pinky1_l" type="revolute"><parent link="pinky1_base_l" /><child link="pinky1_l" /><origin xyz="-0.000000 0.043247 -0.000000" rpy="-0.175045 0.149489 0.319301" /><axis xyz="0.0 0.0 1.0" /><limit lower="0.000000" upper="1.600000" effort="50.0" velocity="4.0" /><dynamics damping="1.0" friction="0.05" /></joint><joint name="pinky2_l" type="revolute"><parent link="pinky1_l" /><child link="pinky2_l" /><origin xyz="-0.000000 0.007820 0.000000" rpy="-0.117001 0.072529 -0.016065" /><axis xyz="0.0 0.0 1.0" /><limit lower="0.000000" upper="1.600000" effort="50.0" velocity="4.0" /><dynamics damping="1.0" friction="0.05" /></joint><joint name="pinky3_l" type="revolute"><parent link="pinky2_l" /><child link="pinky3_l" /><origin xyz="0.000000 0.007725 0.000000" rpy="-0.035199 0.021262 -0.013497" /><axis xyz="0.0 0.0 1.0" /><limit lower="0.000000" upper="1.600000" effort="50.0" velocity="4.0" /><dynamics damping="1.0" friction="0.05" /></joint><joint name="thigh_stretch_l" type="revolute"><parent link="root_x" /><child link="thigh_stretch_l" /><origin xyz="0.059407 0.000000 -0.000000" rpy="2.748947 -1.256079 0.394193" /><axis xyz="0.0 1.0 0.0" /><limit lower="-1.800000" upper="1.800000" effort="50.0" velocity="4.0" /><dynamics damping="1.0" friction="0.05" /></joint><joint name="thigh_twist_l" type="revolute"><parent link="thigh_stretch_l" /><child link="thigh_twist_l" /><origin xyz="-0.000000 -0.000000 0.000000" rpy="-0.000000 0.000000 0.000000" /><axis xyz="1.0 0.0 0.0" /><limit lower="-1.200000" upper="1.200000" effort="50.0" velocity="4.0" /><dynamics damping="1.0" friction="0.05" /></joint><joint name="leg_stretch_l" type="revolute"><parent link="thigh_stretch_l" /><child link="leg_stretch_l" /><origin xyz="-0.000000 0.129607 -0.000000" rpy="-0.000000 0.000000 0.264397" /><axis xyz="0.0 1.0 0.0" /><limit lower="-1.800000" upper="1.800000" effort="50.0" velocity="4.0" /><dynamics damping="1.0" friction="0.05" /></joint><joint name="foot_l" type="revolute"><parent link="leg_stretch_l" /><child link="foot_l" /><origin xyz="0.000000 0.129847 0.000000" rpy="-3.024145 1.553144 1.878010" /><axis xyz="0.0 1.0 0.0" /><limit lower="-0.600000" upper="0.800000" effort="50.0" velocity="4.0" /><dynamics damping="1.0" friction="0.05" /></joint><joint name="toes_01_l" type="revolute"><parent link="foot_l" /><child link="toes_01_l" /><origin xyz="-0.000000 0.064823 0.000000" rpy="-2.796910 0.000186 -3.141524" /><axis xyz="0.0 1.0 0.0" /><limit lower="-0.600000" upper="0.800000" effort="50.0" velocity="4.0" /><dynamics damping="1.0" friction="0.05" /></joint><joint name="leg_twist_l" type="revolute"><parent link="leg_stretch_l" /><child link="leg_twist_l" /><origin xyz="-0.000000 0.064923 0.000000" rpy="-0.000000 0.000000 -0.000000" /><axis xyz="1.0 0.0 0.0" /><limit lower="-1.200000" upper="1.200000" effort="50.0" velocity="4.0" /><dynamics damping="1.0" friction="0.05" /></joint><joint name="thigh_stretch_r" type="revolute"><parent link="root_x" /><child link="thigh_stretch_r" /><origin xyz="-0.059407 0.000000 0.000000" rpy="2.748940 1.256084 -0.394200" /><axis xyz="0.0 1.0 0.0" /><limit lower="-1.800000" upper="1.800000" effort="50.0" velocity="4.0" /><dynamics damping="1.0" friction="0.05" /></joint><joint name="thigh_twist_r" type="revolute"><parent link="thigh_stretch_r" /><child link="thigh_twist_r" /><origin xyz="-0.000000 -0.000000 -0.000000" rpy="0.000000 -0.000000 0.000000" /><axis xyz="1.0 0.0 0.0" /><limit lower="-1.200000" upper="1.200000" effort="50.0" velocity="4.0" /><dynamics damping="1.0" friction="0.05" /></joint><joint name="leg_stretch_r" type="revolute"><parent link="thigh_stretch_r" /><child link="leg_stretch_r" /><origin xyz="-0.000000 0.129607 0.000000" rpy="-0.000000 0.000000 -0.264397" /><axis xyz="0.0 1.0 0.0" /><limit lower="-1.800000" upper="1.800000" effort="50.0" velocity="4.0" /><dynamics damping="1.0" friction="0.05" /></joint><joint name="foot_r" type="revolute"><parent link="leg_stretch_r" /><child link="foot_r" /><origin xyz="0.000000 0.129847 -0.000000" rpy="-3.024103 -1.553146 -1.878052" /><axis xyz="0.0 1.0 0.0" /><limit lower="-0.600000" upper="0.800000" effort="50.0" velocity="4.0" /><dynamics damping="1.0" friction="0.05" /></joint><joint name="toes_01_r" type="revolute"><parent link="foot_r" /><child link="toes_01_r" /><origin xyz="-0.000000 0.064823 -0.000000" rpy="-2.796910 0.000006 3.141592" /><axis xyz="0.0 1.0 0.0" /><limit lower="-0.600000" upper="0.800000" effort="50.0" velocity="4.0" /><dynamics damping="1.0" friction="0.05" /></joint><joint name="leg_twist_r" type="revolute"><parent link="leg_stretch_r" /><child link="leg_twist_r" /><origin xyz="-0.000000 0.064923 -0.000000" rpy="-0.000000 0.000000 -0.000000" /><axis xyz="1.0 0.0 0.0" /><limit lower="-1.200000" upper="1.200000" effort="50.0" velocity="4.0" /><dynamics damping="1.0" friction="0.05" /></joint></robot>