<mujoco model='svg_auto_slam_mapping'>
  <compiler angle='radian'/>
  <option timestep='0.02' gravity='0 0 -9.81'/>
  <worldbody>
    <light name='sun' pos='0 0 8' dir='0 0 -1'/>
    <geom name='floor' type='box' pos='0 0 -0.0250' size='4.6650 2.5400 0.0250' rgba='0.95 0.95 0.95 1'/>
    <geom name='wall_000' type='box' pos='0.0150 2.3000 1.2000' size='4.5600 0.1200 1.2000' rgba='0.28 0.31 0.33 1'/>
    <geom name='wall_001' type='box' pos='-4.4850 0.1400 1.2000' size='0.0600 2.0400 1.2000' rgba='0.28 0.31 0.33 1'/>
    <geom name='wall_002' type='box' pos='-2.9850 1.3400 1.2000' size='0.1200 0.8400 1.2000' rgba='0.28 0.31 0.33 1'/>
    <geom name='wall_003' type='box' pos='-1.1250 0.8000 1.2000' size='0.0600 1.3800 1.2000' rgba='0.28 0.31 0.33 1'/>
    <geom name='wall_004' type='box' pos='3.1350 2.0600 1.2000' size='0.1200 0.1200 1.2000' rgba='0.28 0.31 0.33 1'/>
    <geom name='wall_005' type='box' pos='4.4550 -0.1000 1.2000' size='0.1200 2.2800 1.2000' rgba='0.28 0.31 0.33 1'/>
    <geom name='wall_006' type='box' pos='3.1350 0.2000 1.2000' size='0.1200 0.7800 1.2000' rgba='0.28 0.31 0.33 1'/>
    <geom name='wall_007' type='box' pos='-4.1250 0.5600 1.2000' size='0.3000 0.0600 1.2000' rgba='0.28 0.31 0.33 1'/>
    <geom name='wall_008' type='box' pos='-3.2850 0.5600 1.2000' size='0.1800 0.0600 1.2000' rgba='0.28 0.31 0.33 1'/>
    <geom name='wall_009' type='box' pos='-3.5250 -0.4600 1.2000' size='0.0600 0.4800 1.2000' rgba='0.28 0.31 0.33 1'/>
    <geom name='wall_010' type='box' pos='-4.0050 -0.4600 1.2000' size='0.4200 0.1200 1.2000' rgba='0.28 0.31 0.33 1'/>
    <geom name='wall_011' type='box' pos='-2.6850 -0.4600 1.2000' size='0.7800 0.1200 1.2000' rgba='0.28 0.31 0.33 1'/>
    <geom name='wall_012' type='box' pos='-1.3050 -0.4600 1.2000' size='0.1200 0.1200 1.2000' rgba='0.28 0.31 0.33 1'/>
    <geom name='wall_013' type='box' pos='-0.8250 -0.4600 1.2000' size='0.2400 0.1200 1.2000' rgba='0.28 0.31 0.33 1'/>
    <geom name='wall_014' type='box' pos='1.5150 -0.4600 1.2000' size='1.5000 0.1200 1.2000' rgba='0.28 0.31 0.33 1'/>
    <geom name='wall_015' type='box' pos='0.0750 -1.1200 1.2000' size='0.0600 0.1800 1.2000' rgba='0.28 0.31 0.33 1'/>
    <geom name='wall_016' type='box' pos='-1.9650 -1.2400 1.2000' size='0.5400 0.0600 1.2000' rgba='0.28 0.31 0.33 1'/>
    <geom name='wall_017' type='box' pos='-0.5250 -1.2400 1.2000' size='0.5400 0.0600 1.2000' rgba='0.28 0.31 0.33 1'/>
    <geom name='wall_018' type='box' pos='-3.5250 -1.6000 1.2000' size='0.0600 0.3000 1.2000' rgba='0.28 0.31 0.33 1'/>
    <geom name='wall_019' type='box' pos='-2.3850 -1.8400 1.2000' size='0.1200 0.5400 1.2000' rgba='0.28 0.31 0.33 1'/>
    <geom name='wall_020' type='box' pos='-0.2850 -1.8400 1.2000' size='0.0600 0.5400 1.2000' rgba='0.28 0.31 0.33 1'/>
    <geom name='wall_021' type='box' pos='-4.0050 -1.7800 1.2000' size='0.4200 0.1200 1.2000' rgba='0.28 0.31 0.33 1'/>
    <geom name='wall_022' type='box' pos='-3.3450 -1.7800 1.2000' size='0.1200 0.1200 1.2000' rgba='0.28 0.31 0.33 1'/>
    <geom name='wall_023' type='box' pos='-2.6250 -1.7800 1.2000' size='0.1200 0.1200 1.2000' rgba='0.28 0.31 0.33 1'/>
    <geom name='wall_024' type='box' pos='3.1350 -2.0200 1.2000' size='0.1200 0.3600 1.2000' rgba='0.28 0.31 0.33 1'/>
    <geom name='wall_025' type='box' pos='-1.3050 -2.3200 1.2000' size='0.9600 0.0600 1.2000' rgba='0.28 0.31 0.33 1'/>
    <geom name='wall_026' type='box' pos='1.3950 -2.3200 1.2000' size='1.6200 0.0600 1.2000' rgba='0.28 0.31 0.33 1'/>
    <geom name='wall_027' type='box' pos='3.7950 -2.3200 1.2000' size='0.5400 0.0600 1.2000' rgba='0.28 0.31 0.33 1'/>
    <geom name='furniture_000' type='box' pos='-4.1250 1.7000 0.3250' size='0.3000 0.6000 0.3250' rgba='0.83 0.74 0.57 1'/>
    <geom name='furniture_001' type='box' pos='-3.1650 1.4000 0.3250' size='0.1800 0.9000 0.3250' rgba='0.83 0.74 0.57 1'/>
    <geom name='furniture_002' type='box' pos='-0.4050 2.0600 0.3250' size='0.7800 0.2400 0.3250' rgba='0.83 0.74 0.57 1'/>
    <geom name='furniture_003' type='box' pos='3.5550 2.0000 0.3250' size='0.1800 0.3000 0.3250' rgba='0.83 0.74 0.57 1'/>
    <geom name='furniture_004' type='box' pos='4.1550 2.0000 0.3250' size='0.1800 0.3000 0.3250' rgba='0.83 0.74 0.57 1'/>
    <geom name='furniture_005' type='box' pos='-3.4050 2.0600 0.3250' size='0.0600 0.1200 0.3250' rgba='0.83 0.74 0.57 1'/>
    <geom name='furniture_006' type='box' pos='-2.8050 1.3400 0.3250' size='0.1800 0.8400 0.3250' rgba='0.83 0.74 0.57 1'/>
    <geom name='furniture_007' type='box' pos='3.3150 2.0000 0.3250' size='0.0600 0.1800 0.3250' rgba='0.83 0.74 0.57 1'/>
    <geom name='furniture_008' type='box' pos='3.8550 2.0000 0.3250' size='0.1200 0.1800 0.3250' rgba='0.83 0.74 0.57 1'/>
    <geom name='furniture_009' type='box' pos='4.3950 2.0000 0.3250' size='0.0600 0.1800 0.3250' rgba='0.83 0.74 0.57 1'/>
    <geom name='furniture_010' type='box' pos='-2.0850 1.3400 0.3250' size='0.5400 0.6000 0.3250' rgba='0.83 0.74 0.57 1'/>
    <geom name='furniture_011' type='box' pos='-0.8850 0.6800 0.3250' size='0.3000 1.1400 0.3250' rgba='0.83 0.74 0.57 1'/>
    <geom name='furniture_012' type='box' pos='3.7950 1.7600 0.3250' size='0.0600 0.0600 0.3250' rgba='0.83 0.74 0.57 1'/>
    <geom name='furniture_013' type='box' pos='-3.4050 1.5800 0.3250' size='0.0600 0.1200 0.3250' rgba='0.83 0.74 0.57 1'/>
    <geom name='furniture_014' type='box' pos='1.2150 0.9200 0.3250' size='0.8400 0.3000 0.3250' rgba='0.83 0.74 0.57 1'/>
    <geom name='furniture_015' type='box' pos='-4.2450 0.8600 0.3250' size='0.1800 0.2400 0.3250' rgba='0.83 0.74 0.57 1'/>
    <geom name='furniture_016' type='box' pos='1.2150 0.5600 0.3250' size='0.7200 0.0600 0.3250' rgba='0.83 0.74 0.57 1'/>
    <geom name='furniture_017' type='box' pos='2.4150 0.2600 0.3250' size='0.2400 0.3600 0.3250' rgba='0.83 0.74 0.57 1'/>
    <geom name='furniture_018' type='box' pos='1.2150 0.2600 0.3250' size='0.2400 0.2400 0.3250' rgba='0.83 0.74 0.57 1'/>
    <geom name='furniture_019' type='box' pos='2.1150 0.2600 0.3250' size='0.0600 0.2400 0.3250' rgba='0.83 0.74 0.57 1'/>
    <geom name='furniture_020' type='box' pos='2.7150 0.2600 0.3250' size='0.0600 0.2400 0.3250' rgba='0.83 0.74 0.57 1'/>
    <geom name='furniture_021' type='box' pos='1.2150 -0.2800 0.3250' size='0.7200 0.1800 0.3250' rgba='0.83 0.74 0.57 1'/>
    <geom name='furniture_022' type='box' pos='1.6950 -0.6400 0.3250' size='0.4800 0.1800 0.3250' rgba='0.83 0.74 0.57 1'/>
    <geom name='furniture_023' type='box' pos='1.6950 -0.9400 0.3250' size='0.2400 0.1200 0.3250' rgba='0.83 0.74 0.57 1'/>
    <geom name='furniture_024' type='box' pos='1.6950 -1.1200 0.3250' size='0.1200 0.0600 0.3250' rgba='0.83 0.74 0.57 1'/>
    <geom name='furniture_025' type='box' pos='-2.1450 -1.4200 0.3250' size='0.2400 0.2400 0.3250' rgba='0.83 0.74 0.57 1'/>
    <geom name='furniture_026' type='box' pos='-0.5850 -1.7800 0.3250' size='0.2400 0.6000 0.3250' rgba='0.83 0.74 0.57 1'/>
    <geom name='furniture_027' type='box' pos='2.2950 -1.9600 0.3250' size='0.8400 0.3000 0.3250' rgba='0.83 0.74 0.57 1'/>
    <geom name='furniture_028' type='box' pos='3.4950 -1.9600 0.3250' size='0.2400 0.3000 0.3250' rgba='0.83 0.74 0.57 1'/>
    <geom name='furniture_029' type='box' pos='4.0350 -1.9600 0.3250' size='0.1800 0.3000 0.3250' rgba='0.83 0.74 0.57 1'/>
    <geom name='furniture_030' type='box' pos='-1.9650 -2.0800 0.3250' size='0.0600 0.3000 0.3250' rgba='0.83 0.74 0.57 1'/>
    <geom name='furniture_031' type='box' pos='3.7950 -1.9600 0.3250' size='0.0600 0.1800 0.3250' rgba='0.83 0.74 0.57 1'/>
    <geom name='furniture_032' type='box' pos='4.2750 -1.9600 0.3250' size='0.0600 0.1800 0.3250' rgba='0.83 0.74 0.57 1'/>
    <geom name='furniture_033' type='box' pos='-2.0850 -2.1400 0.3250' size='0.0600 0.2400 0.3250' rgba='0.83 0.74 0.57 1'/>
    <geom name='furniture_034' type='box' pos='-1.8450 -2.1400 0.3250' size='0.0600 0.2400 0.3250' rgba='0.83 0.74 0.57 1'/>
    <geom name='furniture_035' type='box' pos='-1.3050 -2.1400 0.3250' size='0.2400 0.2400 0.3250' rgba='0.83 0.74 0.57 1'/>
    <geom name='furniture_036' type='box' pos='3.1950 -2.0200 0.3250' size='0.0600 0.1200 0.3250' rgba='0.83 0.74 0.57 1'/>
    <geom name='furniture_037' type='box' pos='-1.0050 -2.2000 0.3250' size='0.0600 0.1800 0.3250' rgba='0.83 0.74 0.57 1'/>
    <geom name='furniture_038' type='box' pos='0.8550 -2.2000 0.3250' size='0.3600 0.1800 0.3250' rgba='0.83 0.74 0.57 1'/>
    <body name='robot' pos='0 0 0.12'>
      <joint name='robot_x' type='slide' axis='1 0 0'/>
      <joint name='robot_y' type='slide' axis='0 1 0'/>
      <joint name='robot_yaw' type='hinge' axis='0 0 1'/>
      <geom name='robot_base' type='cylinder' pos='0 0 0' size='0.16 0.06' rgba='0.16 0.52 0.69 1'/>
      <site name='lidar_origin' pos='0 0 0.02' size='0.015'/>
    </body>
  </worldbody>
  <keyframe>
    <key name='start' qpos='0.0050 -0.0100 0'/>
  </keyframe>
</mujoco>
